Workbook

Sheet แผนผลิต
B1: DOCNO. : FM - PL - 016 | N1: FROM | AA1: TITLE : แผนสั่งผลิตสินค้า Wonton & Noodle Plant 3
B2: REVISON : 0 | N2: EFFECTIVE DATE : 16 JULY 2024 | AA2: อายุการเก็บรักษา : 6 เดือน
B3: Date Report | D3: ซ่อน | E3: ซ่อน | F3: ซ่อน | G3: 46274 | L3: ซ่อน | AE3: =(P4011*Q4011*R4011*V4011)/0.54 -> 226.66667
A4: R T C | B4: แผนผลิต Date | C4: แผน LOAD Date | D4: year | E4: WEEK | F4: Month | G4: No-. order | H4: Country | I4: Country2 | J4: Customer | K4: Group1 | L4: Group2 | M4: Product | N4: CODE | O4: Packing | P4: cups | Q4: Pcs./Cup | R4: WT/Pcs | S4: RM | T4: Dip | U4: Soup | V4: QTY | W4: Stock จริง | X4: Stock สำรอง | Y4: Short/cs | Z4: Short/cup | AA4: Short Raw Wonton /Pcs. | AB4: ผงซุป/tray | AC4: ผงซุป | AD4: Remaek | AE4: WT/ PD | AF4: WT/ HO (Tons.) | AH4: WT | AI4: Order ถ้วย | AJ4: ผลิต ถ้วย | AP4: ดิวเข้า PK | AQ4: ฟิล์ม | AR4: ถ้วย | AS4: ฝา | AT4: INNER | AU4: แผ่นกั้น | AV4: M | AW4: M/ก้น | AX4: ถุง | AY4: STK-ฝา | AZ4: STK-ถ้วย | BA4: STK-ข้างถ้วย | BB4: ผงซุป
B5: 45292 | D5: =IF(B5="","",YEAR(B5)) -> 2024 | E5: =VLOOKUP($B5,Week!$A$1:$C$1462,2,0) -> Week1 | F5: =IF(B5="","",TEXT(B5,"[$-409]mmm")) -> Jan | AK5: 66S03 | AM5: =AG5*Z5 -> 0 | AN5: =B5 -> 45292 | AO5: 2
B6: 45293 | D6: =IF(B6="","",YEAR(B6)) -> 2024 | E6: =VLOOKUP($B6,Week!$A$1:$C$1462,2,0) -> Week1 | F6: =IF(B6="","",TEXT(B6,"[$-409]mmm")) -> Jan | AK6: 66S03 | AM6: =AG6*Z6 -> 0 | AN6: =B6 -> 45293 | AO6: 2
A7: T | B7: 45294 | C7: 45207 | D7: =IF(B7="","",YEAR(B7)) -> 2024 | E7: =VLOOKUP($B7,Week!$A$1:$C$1462,2,0) -> Week1 | F7: =IF(B7="","",TEXT(B7,"[$-409]mmm")) -> Jan | G7: DRY2300557 | H7: USA | I7: CPFNW | J7: Bellisio | K7: C-WT in tray no egg | L7: Cooked Wonton | M7: COOKED WONTON 6 pcs. | N7: 082S8BW08012P00001 | O7: 117*2tray*8in | P7: 16 | Q7: 6 | R7: 0.00813 | S7: M | T7: Salt | U7: Sesame 15g | V7: 901 | X7: 901 | Y7: =(W7+X7)-V7 -> 0 | Z7: =IF(Y7<0,((V7*P7)-((W7+X7)*P7)),0) -> 0 | AB7: 1 | AC7: =AB7*V7*P7 -> 14416 | AD7: cap 3000 tray/hr. | AG7: =MID(O7,1,3)/1000 -> 0.117 | AH7: =(Z7*AG7)/1000 -> 0 | AI7: =V7*P7 -> 14416 | AK7: 66S03 | AL7: RES_KL3_FUR_FREEZE_COOK | AM7: =AG7*Z7 -> 0 | AN7: =B7 -> 45294 | AO7: 2 | AR7: 12080450 | AT7: 12083198 | AV7: 12080491 | AX7: ซอง 12080447/ม้วน
A8: STK ตรุษจีน | B8: 45294 | C8: 45299 | D8: =IF(B8="","",YEAR(B8)) -> 2024 | E8: =VLOOKUP($B8,Week!$A$1:$C$1462,2,0) -> Week1 | F8: =IF(B8="","",TEXT(B8,"[$-409]mmm")) -> Jan | G8: ขายภายใน | H8: .7-11 | I8: CPFGS | J8: ถ้วยขาวพิมพ์ลายใหม่ | K8: Wonton | L8: Cooked Wonton | M8: Cooked Wonton No Egg .7-11 | N8: 082S81A24005P06001 | O8: 130g*24 | P8: 24 | Q8: 5 | R8: 0.0062 | S8: SS | T8: STPP | U8: Regular | V8: 2878 | W8: 2878 | Y8: =(W8+X8)-V8 -> 0 | Z8: =IF(Y8<0,((V8*P8)-((W8+X8)*P8)),0) -> 0 | AD8: STK ตรุษจีน | AG8: =MID(O8,1,3)/1000 -> 0.13 | AH8: =(Z8*AG8)/1000 -> 0 | AI8: =V8*P8 -> 69072 | AK8: 66S03 | AL8: RES_KL3_FUR_FREEZE_COOK | AM8: =AG8*Z8 -> 0 | AN8: =B8 -> 45294 | AO8: 2 | AP8: 13/1/22 | AQ8: 12071839 | AR8: 12078867 | AS8: 12068233 | AV8: 12062075 | AY8: 12078868
A9: เริ่มหมึกพิพม์ใหม่ | B9: 45294 | C9: 45299 | D9: =IF(B9="","",YEAR(B9)) -> 2024 | E9: =VLOOKUP($B9,Week!$A$1:$C$1462,2,0) -> Week1 | F9: =IF(B9="","",TEXT(B9,"[$-409]mmm")) -> Jan | G9: DRY2300667 | H9: Netherlands | I9: CPFNW | J9: Westbridge Foods Limited | K9: Wonton ND+V+TY | L9: Cooked Wonton | M9: Cooked Wonton ND No Egg with Pumpkin + Vegetable 5 pcs tomyam | N9: 082SJWE24005P01001 | O9: 307g*4c*6in | P9: 24 | Q9: 5 | R9: 0.0075 | S9: M | T9: Salt | U9: TYEX+CO | V9: 924 | W9: =924 -> 924 | Y9: =(W9+X9)-V9 -> 0 | Z9: =IF(Y9<0,((V9*P9)-((W9+X9)*P9)),0) -> 0 | AD9: เริ่มหมึกพิพม์ใหม่ | AG9: =MID(O9,1,3)/1000 -> 0.307 | AH9: =(Z9*AG9)/1000 -> 0 | AI9: =V9*P9 -> 22176 | AK9: 66S03 | AL9: RES_KL3_FUR_FREEZE_COOK | AM9: =AG9*Z9 -> 0 | AN9: =B9 -> 45294 | AO9: 2 | AP9: รอแบบ | AQ9: 12063755 | AR9: 12061353 | AS9: 12061354 | AT9: 12084023 | AV9: 12084228
A10: R | B10: 45294 | C10: 45299 | D10: =IF(B10="","",YEAR(B10)) -> 2024 | E10: =VLOOKUP($B10,Week!$A$1:$C$1462,2,0) -> Week1 | F10: =IF(B10="","",TEXT(B10,"[$-409]mmm")) -> Jan | G10: DRY2300541 | H10: SG | I10: CPFNW | J10: CPI SINGAPORE | K10: R-Wonton egg past | L10: Raw Wonton | M10: Raw Wonton 12 pcs | N10: 082I93B20012P06001 | O10: 154g*20in | P10: 20 | Q10: 12 | R10: 0.00681 | S10: S | T10: STPP | U10: ซุปซอง 5g. | V10: =1000-61-58-47-62-67-16-25 -> 664 | W10: 664 | Y10: =(W10+X10)-V10 -> 0 | Z10: =IF(Y10<0,((V10*P10)-((W10+X10)*P10)),0) -> 0 | AA10: =Q10*Z10 -> 0 | AB10: 2 | AC10: =Z10*AB10 -> 0 | AD10: ห่อแบบสุก | AG10: =MID(O10,1,3)/1000 -> 0.154 | AH10: =(Z10*AG10)/1000 -> 0 | AI10: =V10*P10 -> 13280 | AK10: 66S03 | AL10: RES_KL3_FUR_FREEZE_RAW | AM10: =AG10*Z10 -> 0 | AN10: =B10 -> 45294 | AO10: 2 | AP10: 20/12/21 | AQ10: 12045770 | AR10: 12019692 | AT10: 12055901 | AV10: 12055893 | AX10: 12045309(248)
A11: STK ตรุษจีน | B11: 45295 | C11: 45299 | D11: =IF(B11="","",YEAR(B11)) -> 2024 | E11: =VLOOKUP($B11,Week!$A$1:$C$1462,2,0) -> Week1 | F11: =IF(B11="","",TEXT(B11,"[$-409]mmm")) -> Jan | G11: ขายภายใน | H11: .7-11 | I11: CPFGS | J11: ถ้วยขาวพิมพ์ลายใหม่ | K11: Wonton | L11: Cooked Wonton | M11: Cooked Wonton No Egg .7-11 | N11: 082S81A24005P06001 | O11: 130g*24 | P11: 24 | Q11: 5 | R11: 0.0062 | S11: SS | T11: STPP | U11: Regular | V11: =8334-2878+36 -> 5492 | W11: =4685+262+262+283 -> 5492 | Y11: =(W11+X11)-V11 -> 0 | Z11: =IF(Y11<0,((V11*P11)-((W11+X11)*P11)),0) -> 0 | AD11: STK ตรุษจีน | AG11: =MID(O11,1,3)/1000 -> 0.13 | AH11: =(Z11*AG11)/1000 -> 0 | AI11: =V11*P11 -> 131808 | AK11: 66S03 | AL11: RES_KL3_FUR_FREEZE_COOK | AM11: =AG11*Z11 -> 0 | AN11: =B11 -> 45295 | AO11: 2 | AP11: 13/1/22 | AQ11: 12071839 | AR11: 12078867 | AS11: 12068233 | AV11: 12062075 | AY11: 12078868
B12: 45295 | C12: 45307 | D12: =IF(B12="","",YEAR(B12)) -> 2024 | E12: =VLOOKUP($B12,Week!$A$1:$C$1462,2,0) -> Week1 | F12: =IF(B12="","",TEXT(B12,"[$-409]mmm")) -> Jan | G12: DRY2300666 | H12: UK | I12: CPFNW | J12: Westbridge Foods Limited | K12: Wonton ND+V+TY | L12: Cooked Wonton | M12: Cooked Wonton ND No Egg with Pumpkin + Vegetable 5 pcs tomyam | N12: 082SJWE24005P00001 | O12: 307g*4c*6in | P12: 24 | Q12: 5 | R12: 0.0075 | S12: M | T12: Salt | U12: TYEX+CO | V12: 924 | W12: =5+826+8+85 -> 924 | Y12: =(W12+X12)-V12 -> 0 | Z12: =IF(Y12<0,((V12*P12)-((W12+X12)*P12)),0) -> 0 | AG12: =MID(O12,1,3)/1000 -> 0.307 | AH12: =(Z12*AG12)/1000 -> 0 | AI12: =V12*P12 -> 22176 | AK12: 66S03 | AL12: RES_KL3_FUR_FREEZE_COOK | AM12: =AG12*Z12 -> 0 | AN12: =B12 -> 45295 | AO12: 2 | AP12: รอแบบ | AQ12: 12063755 | AR12: 12061353 | AS12: 12061354 | AT12: 12084023 | AV12: 12084228
A13: R | B13: 45295 | C13: 45299 | D13: =IF(B13="","",YEAR(B13)) -> 2024 | E13: =VLOOKUP($B13,Week!$A$1:$C$1462,2,0) -> Week1 | F13: =IF(B13="","",TEXT(B13,"[$-409]mmm")) -> Jan | G13: KL2300030 | H13: China | I13: China | J13: Sam's (Shanghai) Investment Co., Ltd. | K13: R-Wonton no egg | L13: Raw Wonton | M13: Raw Wonton 60 pcs | N13: 082I9WN08060P00001 | O13: 750g*8in | P13: 8 | Q13: 60 | R13: 0.00681 | S13: S | T13: STPP | U13: ซุปซอง 5g. | V13: 546 | W13: =5+541 -> 546 | Y13: =(W13+X13)-V13 -> 0 | Z13: =IF(Y13<0,((V13*P13)-((W13+X13)*P13)),0) -> 0 | AA13: =Q13*Z13 -> 0 | AB13: 6 | AC13: =Z13*AB13 -> 0 | AG13: =MID(O13,1,3)/1000 -> 0.75 | AH13: =(Z13*AG13)/1000 -> 0 | AI13: =V13*P13 -> 4368 | AK13: 66S03 | AL13: RES_KL3_FUR_FREEZE_RAW | AM13: =AG13*Z13 -> 0 | AN13: =B13 -> 45295 | AO13: 2 | AP13: 10/11/21 | AQ13: 12004862 | AR13: 12080753 | AT13: 12082897 | AV13: 12082898 | AW13: 12082899 | AX13: 12080741(117)
A14: T | B14: 45296 | C14: 45207 | D14: =IF(B14="","",YEAR(B14)) -> 2024 | E14: =VLOOKUP($B14,Week!$A$1:$C$1462,2,0) -> Week1 | F14: =IF(B14="","",TEXT(B14,"[$-409]mmm")) -> Jan | G14: DRY2300557 | H14: USA | I14: CPFNW | J14: Bellisio | K14: C-WT in tray no egg | L14: Cooked Wonton | M14: COOKED WONTON 6 pcs. | N14: 082S8BW08012P00001 | O14: 117*2tray*8in | P14: 16 | Q14: 6 | R14: 0.00813 | S14: M | T14: Salt | U14: Sesame 15g | V14: 599 | W14: 599 | Y14: =(W14+X14)-V14 -> 0 | Z14: =IF(Y14<0,((V14*P14)-((W14+X14)*P14)),0) -> 0 | AB14: 1 | AC14: =AB14*V14*P14 -> 9584 | AD14: cap 3000 tray/hr. | AG14: =MID(O14,1,3)/1000 -> 0.117 | AH14: =(Z14*AG14)/1000 -> 0 | AI14: =V14*P14 -> 9584 | AK14: 66S03 | AL14: RES_KL3_FUR_FREEZE_COOK | AM14: =AG14*Z14 -> 0 | AN14: =B14 -> 45296 | AO14: 2 | AR14: 12080450 | AT14: 12083198 | AV14: 12080491 | AX14: ซอง 12080447/ม้วน
B15: 45296 | D15: =IF(B15="","",YEAR(B15)) -> 2024 | E15: =VLOOKUP($B15,Week!$A$1:$C$1462,2,0) -> Week1 | F15: =IF(B15="","",TEXT(B15,"[$-409]mmm")) -> Jan | G15: ขายภายใน | H15: .7-11 | I15: CPFGS | J15: ถ้วยขาวพิมพ์ลายใหม่ | K15: Wonton | L15: Cooked Wonton | M15: Cooked Wonton No Egg .7-11 | N15: 082S81A24005P06001 | O15: 130g*24 | P15: 24 | Q15: 5 | R15: 0.0062 | S15: SS | T15: STPP | U15: Regular | V15: 1997 | W15: =2804-262-262-283 -> 1997 | Y15: =(W15+X15)-V15 -> 0 | Z15: =IF(Y15<0,((V15*P15)-((W15+X15)*P15)),0) -> 0 | AG15: =MID(O15,1,3)/1000 -> 0.13 | AH15: =(Z15*AG15)/1000 -> 0 | AI15: =V15*P15 -> 47928 | AK15: 66S03 | AL15: RES_KL3_FUR_FREEZE_COOK | AM15: =AG15*Z15 -> 0 | AN15: =B15 -> 45296 | AO15: 2 | AP15: 13/1/22 | AQ15: 12071839 | AR15: 12078867 | AS15: 12068233 | AV15: 12062075 | AY15: 12078868
A16: R | B16: 45296 | C16: 45299 | D16: =IF(B16="","",YEAR(B16)) -> 2024 | E16: =VLOOKUP($B16,Week!$A$1:$C$1462,2,0) -> Week1 | F16: =IF(B16="","",TEXT(B16,"[$-409]mmm")) -> Jan | G16: KL2300030 | H16: China | I16: China | J16: Sam's (Shanghai) Investment Co., Ltd. | K16: R-Wonton no egg | L16: Raw Wonton | M16: Raw Wonton 60 pcs | N16: 082I9WN08060P00001 | O16: 750g*8in | P16: 8 | Q16: 60 | R16: 0.00681 | S16: S | T16: STPP | U16: ซุปซอง 5g. | V16: 555 | W16: 555 | Y16: =(W16+X16)-V16 -> 0 | Z16: =IF(Y16<0,((V16*P16)-((W16+X16)*P16)),0) -> 0 | AA16: =Q16*Z16 -> 0 | AB16: 6 | AC16: =Z16*AB16 -> 0 | AG16: =MID(O16,1,3)/1000 -> 0.75 | AH16: =(Z16*AG16)/1000 -> 0 | AI16: =V16*P16 -> 4440 | AK16: 66S03 | AL16: RES_KL3_FUR_FREEZE_RAW | AM16: =AG16*Z16 -> 0 | AN16: =B16 -> 45296 | AO16: 2 | AP16: 10/11/21 | AQ16: 12004862 | AR16: 12080753 | AT16: 12082897 | AV16: 12082898 | AW16: 12082899 | AX16: 12080741(117)
A17: เก็บตก | B17: 45297 | C17: 45299 | D17: =IF(B17="","",YEAR(B17)) -> 2024 | E17: =VLOOKUP($B17,Week!$A$1:$C$1462,2,0) -> Week1 | F17: =IF(B17="","",TEXT(B17,"[$-409]mmm")) -> Jan | G17: DRY2300557 | H17: USA | I17: CPFNW | J17: Bellisio Foods, Inc. | K17: Minced ND | L17: Cooked Wonton | M17: Cooked Minced Wonton Noodle No Egg | N17: 082SRBW08005P00001 | O17: 258g*8 | P17: 8 | Q17: 5 | R17: 0.006 | S17: BK | T17: Salt | U17: Regular | V17: 202 | W17: 202 | Y17: =(W17+X17)-V17 -> 0 | Z17: =IF(Y17<0,((V17*P17)-((W17+X17)*P17)),0) -> 0 | AG17: =MID(O17,1,3)/1000 -> 0.258 | AH17: 0.26622 | AI17: =V17*P17 -> 1616 | AK17: 66S03 | AL17: RES_KL3_FUR_FREEZE_COOK | AM17: =AG17*Z17 -> 0 | AN17: =B17 -> 45297 | AO17: 2 | AQ17: 12071839 | AR17: 12042650 | AS17: 12042649 | AT17: 12084100 | AV17: 12084001
B18: 45297 | C18: 45306 | D18: =IF(B18="","",YEAR(B18)) -> 2024 | E18: =VLOOKUP($B18,Week!$A$1:$C$1462,2,0) -> Week1 | F18: =IF(B18="","",TEXT(B18,"[$-409]mmm")) -> Jan | G18: ขายภายใน | H18: MTFS | I18: CPFGS | J18: ซีพีเอฟ เทรดดิ้ง | K18: E+Wonton NDE | L18: Cooked Wonton | M18: Cooked Wonton ND with egg V-Food | N18: 082SJ3Q12003P07001 | O18: 226g*12 | P18: 12 | Q18: 3 | R18: 0.008 | S18: M | T18: STPP | U18: Regular | V18: 515 | W18: =2+513 -> 515 | Y18: =(W18+X18)-V18 -> 0 | Z18: =IF(Y18<0,((V18*P18)-((W18+X18)*P18)),0) -> 0 | AG18: =MID(O18,1,3)/1000 -> 0.226 | AH18: =(Z18*AG18)/1000 -> 0 | AI18: =V18*P18 -> 6180 | AK18: 66S03 | AL18: RES_KL3_FUR_FREEZE_COOK | AM18: =AG18*Z18 -> 0 | AN18: =B18 -> 45297 | AO18: 2 | AP18: 25/11/21 | AR18: 12042650 | AS18: 12042649 | AV18: 12083156 | AY18: 12083147 | AZ18: 12083148
B19: 45297 | C19: 45320 | D19: =IF(B19="","",YEAR(B19)) -> 2024 | E19: =VLOOKUP($B19,Week!$A$1:$C$1462,2,0) -> Week1 | F19: =IF(B19="","",TEXT(B19,"[$-409]mmm")) -> Jan | G19: ขายภายใน | H19: MTFS | I19: CPFGS | J19: ซีพีเอฟ เทรดดิ้ง | K19: E+Wonton TY | L19: Cooked Wonton | M19: Cooked Wonton Tomyum with egg.V-Food TY | N19: 082S83Q12005P04001 | O19: 115g*12 | P19: 12 | Q19: 5 | R19: 0.008 | S19: M | T19: STPP | U19: TYTB3C 30G | V19: 320 | W19: 320 | Y19: =(W19+X19)-V19 -> 0 | Z19: =IF(Y19<0,((V19*P19)-((W19+X19)*P19)),0) -> 0 | AB19: 1 | AC19: =Z19*AB19 -> 0 | AG19: =MID(O19,1,3)/1000 -> 0.115 | AH19: =(Z19*AG19)/1000 -> 0 | AI19: =V19*P19 -> 3840 | AK19: 66S03 | AL19: RES_KL3_FUR_FREEZE_COOK | AM19: =AG19*Z19 -> 0 | AN19: =B19 -> 45297 | AO19: 2 | AP19: 25/11/21 | AQ19: 12071839 | AR19: 12047514 | AS19: 12047515 | AV19: 12072447 | AY19: 12064574 | AZ19: 12064576
B20: 45297 | C20: 45299 | D20: =IF(B20="","",YEAR(B20)) -> 2024 | E20: =VLOOKUP($B20,Week!$A$1:$C$1462,2,0) -> Week1 | F20: =IF(B20="","",TEXT(B20,"[$-409]mmm")) -> Jan | G20: ขายภายใน | H20: MTFS | I20: CPFGS | J20: ซีพีเอฟ เทรดดิ้ง | K20: E+Wonton | L20: Cooked Wonton | M20: Cooked Wonton with egg V-Food | N20: 082S83Q12005P05001 | O20: 145g*12 | P20: 12 | Q20: 5 | R20: 0.008 | S20: M | T20: STPP | U20: Regular | V20: 2919 | W20: =21+1+2897 -> 2919 | Y20: =(W20+X20)-V20 -> 0 | Z20: =IF(Y20<0,((V20*P20)-((W20+X20)*P20)),0) -> 0 | AG20: =MID(O20,1,3)/1000 -> 0.145 | AH20: =(Z20*AG20)/1000 -> 0 | AI20: =V20*P20 -> 35028 | AK20: 66S03 | AL20: RES_KL3_FUR_FREEZE_COOK | AM20: =AG20*Z20 -> 0 | AN20: =B20 -> 45297 | AO20: 2 | AP20: 10/12/21 | AQ20: 12071839 | AR20: 12047514 | AS20: 12047515 | AV20: 12080617 | AY20: 12080618 | AZ20: 12080619
B21: 45297 | C21: 45309 | D21: =IF(B21="","",YEAR(B21)) -> 2024 | E21: =VLOOKUP($B21,Week!$A$1:$C$1462,2,0) -> Week1 | F21: =IF(B21="","",TEXT(B21,"[$-409]mmm")) -> Jan | G21: ขายภายใน | H21: MTFS | I21: CPFGS | J21: ซีพีเอฟ เทรดดิ้ง | K21: E+Wonton | L21: Cooked Wonton | M21: Cooked Wonton Multipack with Egg 270g | N21: 082S83Q18005P05001 | O21: 270g*3B*6B | P21: 18 | Q21: 5 | R21: 0.008 | S21: M | T21: STPP | U21: ซุปซอง 5g. | V21: 1700 | W21: =999+123+578 -> 1700 | Y21: =(W21+X21)-V21 -> 0 | Z21: =IF(Y21<0,((V21*P21)-((W21+X21)*P21)),0) -> 0 | AB21: 1 | AC21: =Z21*AB21 -> 0 | AG21: =(MID(O21,1,3)/1000)/3 -> 0.09 | AH21: =(Z21*AG21)/1000 -> 0 | AI21: =V21*P21 -> 30600 | AK21: 66S03 | AL21: RES_KL3_FUR_FREEZE_COOK | AM21: =AG21*Z21 -> 0 | AN21: =B21 -> 45297 | AO21: 2 | AP21: 10/12/21 | AV21: 12080791 | AW21: ถุงพิมพ์ 12080790 | AX21: 12074457(18/กก.)
B22: 45297 | C22: 45299 | D22: =IF(B22="","",YEAR(B22)) -> 2024 | E22: =VLOOKUP($B22,Week!$A$1:$C$1462,2,0) -> Week1 | F22: =IF(B22="","",TEXT(B22,"[$-409]mmm")) -> Jan | G22: ขายภายใน | H22: .7-11 | I22: CPFGS | J22: ซีพีเอฟ เทรดดิ้ง | K22: E+Wonton+หมาล่า | L22: Cooked Wonton | M22: เกี๊ยวกุ้งจักรพรรดิซุปหมาล่า (ตรา ซีพี)_7E | N22: 082S81A24005P0B001 | O22: 143g*24 | P22: 24 | Q22: 5 | R22: 0.0062 | S22: SS | T22: STPP | U22: หมาล่า | V22: 2030 | W22: =4756-4707+1981 -> 2030 | Y22: =(W22+X22)-V22 -> 0 | Z22: =IF(Y22<0,((V22*P22)-((W22+X22)*P22)),0) -> 0 | AG22: =MID(O22,1,3)/1000 -> 0.143 | AH22: =(Z22*AG22)/1000 -> 0 | AI22: =V22*P22 -> 48720 | AK22: 66S03 | AL22: RES_KL3_FUR_FREEZE_COOK | AM22: =AG22*Z22 -> 0 | AN22: =B22 -> 45297 | AO22: 2 | AP22: 18/12/21 | AQ22: 12071839 | AR22: 12047514 | AS22: 12047515 | AV22: 12080613 | AY22: 12080614 | AZ22: 12080616
A23: R | B23: 45297 | C23: 45299 | D23: =IF(B23="","",YEAR(B23)) -> 2024 | E23: =VLOOKUP($B23,Week!$A$1:$C$1462,2,0) -> Week1 | F23: =IF(B23="","",TEXT(B23,"[$-409]mmm")) -> Jan | G23: KL2300030 | H23: China | I23: China | J23: Sam's (Shanghai) Investment Co., Ltd. | K23: R-Wonton no egg | L23: Raw Wonton | M23: Raw Wonton 60 pcs | N23: 082I9WN08060P00001 | O23: 750g*8in | P23: 8 | Q23: 60 | R23: 0.00681 | S23: S | T23: STPP | U23: ซุปซอง 5g. | V23: =1408-546-555 -> 307 | W23: 307 | Y23: =(W23+X23)-V23 -> 0 | Z23: =IF(Y23<0,((V23*P23)-((W23+X23)*P23)),0) -> 0 | AA23: =Q23*Z23 -> 0 | AB23: 6 | AC23: =Z23*AB23 -> 0 | AG23: =MID(O23,1,3)/1000 -> 0.75 | AH23: =(Z23*AG23)/1000 -> 0 | AI23: =V23*P23 -> 2456 | AK23: 66S03 | AL23: RES_KL3_FUR_FREEZE_RAW | AM23: =AG23*Z23 -> 0 | AN23: =B23 -> 45297 | AO23: 2 | AP23: 10/11/21 | AQ23: 12004862 | AR23: 12080753 | AT23: 12082897 | AV23: 12082898 | AW23: 12082899 | AX23: 12080741(117)
A24: R | B24: 45297 | C24: 45330 | D24: =IF(B24="","",YEAR(B24)) -> 2024 | E24: =VLOOKUP($B24,Week!$A$1:$C$1462,2,0) -> Week1 | F24: =IF(B24="","",TEXT(B24,"[$-409]mmm")) -> Jan | G24: KL2300038 | H24: China | I24: China | J24: Charoen Pokphand Import&Export Trading (Shanghai) Co., Ltd | K24: R-Wonton no egg | L24: Raw Wonton | M24: Raw Wonton 12 pcs | N24: 082I95J20012P04001 | O24: 144g*20in | P24: 20 | Q24: 12 | R24: 0.00681 | S24: S | T24: STPP | U24: ซุปซอง 5g. | V24: 957 | W24: =761 -> 761 | X24: =(3920)/20 -> 196 | Y24: =(W24+X24)-V24 -> 0 | Z24: =IF(Y24<0,((V24*P24)-((W24+X24)*P24)),0) -> 0 | AA24: =Q24*Z24 -> 0 | AB24: 2 | AC24: =Z24*AB24 -> 0 | AD24: pkเข้า5/1 | AG24: =MID(O24,1,3)/1000 -> 0.144 | AH24: =(Z24*AG24)/1000 -> 0 | AI24: =V24*P24 -> 19140 | AK24: 66S03 | AL24: RES_KL3_FUR_FREEZE_RAW | AM24: =AG24*Z24 -> 0 | AN24: =B24 -> 45297 | AO24: 2 | AQ24: 12071839 | AR24: 12019692 | AT24: 12026905 | AV24: 12027007 | AX24: 12045309(248)
B25: 45298 | D25: =IF(B25="","",YEAR(B25)) -> 2024 | E25: =VLOOKUP($B25,Week!$A$1:$C$1462,2,0) -> Week1 | F25: =IF(B25="","",TEXT(B25,"[$-409]mmm")) -> Jan | M25: เครื่องจักรเสีย | AK25: 66S03 | AM25: =AG25*Z25 -> 0 | AN25: =B25 -> 45298 | AO25: 2
A26: T | B26: 45298 | C26: 45314 | D26: =IF(B26="","",YEAR(B26)) -> 2024 | E26: =VLOOKUP($B26,Week!$A$1:$C$1462,2,0) -> Week1 | F26: =IF(B26="","",TEXT(B26,"[$-409]mmm")) -> Jan | G26: DRY2300670 | H26: Korea | I26: CPFNW | J26: Emart | K26: C-WT in tray no egg | L26: Cooked Wonton | M26: COOKED WONTON 6 pcs. | N26: 082S8EJ12012P00001 | O26: 141*2tray*12in | P26: 24 | Q26: 6 | R26: 0.0062 | S26: SS | T26: Salt | U26: Sesame 15g | V26: =2799 -> 2799 | W26: =532 -> 532 | X26: =(118+27995)/12 -> 2342.75 | Y26: =(W26+X26)-V26 -> 75.75 | Z26: =IF(Y26<0,((V26*P26)-((W26+X26)*P26)),0) -> 0 | AB26: 1 | AC26: =AB26*V26*P26 -> 67176 | AD26: NEWPACKAGE | AG26: =MID(O26,1,3)/1000 -> 0.141 | AH26: =(Z26*AG26)/1000 -> 0 | AI26: =V26*P26 -> 67176 | AK26: 66S03 | AL26: RES_KL3_FUR_FREEZE_COOK | AM26: =AG26*Z26 -> 0 | AN26: =B26 -> 45298 | AO26: 2 | AR26: 12080450 | AT26: 12083198 | AV26: 12080491 | AX26: ซอง 12080447/ม้วน
B27: 45299 | C27: 45303 | D27: =IF(B27="","",YEAR(B27)) -> 2024 | E27: =VLOOKUP($B27,Week!$A$1:$C$1462,2,0) -> Week2 | F27: =IF(B27="","",TEXT(B27,"[$-409]mmm")) -> Jan | G27: DRY2300600 | H27: USA | I27: CPFNW | J27: Bellisio Foods, Inc. | K27: Wonton ND+V | L27: Cooked Wonton | M27: Cooked Wonton ND No Egg with Pumpkin + Yu Choy Low sodium | N27: 082SJBW36005P00001 | O27: 308g*6c*6in | P27: 36 | Q27: 5 | R27: 0.0075 | S27: HC | T27: Salt | U27: Y3 | V27: =792-661 -> 131 | W27: =792-661 -> 131 | Y27: =(W27+X27)-V27 -> 0 | Z27: =IF(Y27<0,((V27*P27)-((W27+X27)*P27)),0) -> 0 | AG27: =MID(O27,1,3)/1000 -> 0.308 | AH27: =(Z27*AG27)/1000 -> 0 | AI27: =V27*P27 -> 4716 | AK27: 66S03 | AL27: RES_KL3_FUR_FREEZE_COOK | AM27: =AG27*Z27 -> 0 | AN27: =B27 -> 45299 | AO27: 2 | AQ27: 12063755 | AR27: 12061353 | AS27: 12061354 | AT27: 12068566 | AV27: 12068564 | AW27: 12062153 | AY27: 12068565
B28: 45299 | C28: 45303 | D28: =IF(B28="","",YEAR(B28)) -> 2024 | E28: =VLOOKUP($B28,Week!$A$1:$C$1462,2,0) -> Week2 | F28: =IF(B28="","",TEXT(B28,"[$-409]mmm")) -> Jan | G28: DRY2300594 | H28: USA | I28: CPFNW | J28: Bellisio Foods, Inc. | K28: Wonton ND+V | L28: Cooked Wonton | M28: Cooked Wonton ND No Egg with Pumpkin + Yu Choy Low sodium | N28: 082SJBW36005P00001 | O28: 308g*6c*6in | P28: 36 | Q28: 5 | R28: 0.0075 | S28: HC | T28: Salt | U28: Y3 | V28: 792 | W28: 792 | Y28: =(W28+X28)-V28 -> 0 | Z28: =IF(Y28<0,((V28*P28)-((W28+X28)*P28)),0) -> 0 | AG28: =MID(O28,1,3)/1000 -> 0.308 | AH28: =(Z28*AG28)/1000 -> 0 | AI28: =V28*P28 -> 28512 | AK28: 66S03 | AL28: RES_KL3_FUR_FREEZE_COOK | AM28: =AG28*Z28 -> 0 | AN28: =B28 -> 45299 | AO28: 2 | AQ28: 12063755 | AR28: 12061353 | AS28: 12061354 | AT28: 12068566 | AV28: 12068564 | AW28: 12062153 | AY28: 12068565
B29: 45299 | C29: 45303 | D29: =IF(B29="","",YEAR(B29)) -> 2024 | E29: =VLOOKUP($B29,Week!$A$1:$C$1462,2,0) -> Week2 | F29: =IF(B29="","",TEXT(B29,"[$-409]mmm")) -> Jan | G29: DRY2300595 | H29: USA | I29: CPFNW | J29: Bellisio Foods, Inc. | K29: Wonton ND+V | L29: Cooked Wonton | M29: Cooked Wonton ND No Egg with Pumpkin + Yu Choy Low sodium | N29: 082SJBW36005P00001 | O29: 308g*6c*6in | P29: 36 | Q29: 5 | R29: 0.0075 | S29: HC | T29: Salt | U29: Y3 | V29: 792 | W29: 792 | Y29: =(W29+X29)-V29 -> 0 | Z29: =IF(Y29<0,((V29*P29)-((W29+X29)*P29)),0) -> 0 | AG29: =MID(O29,1,3)/1000 -> 0.308 | AH29: =(Z29*AG29)/1000 -> 0 | AI29: =V29*P29 -> 28512 | AK29: 66S03 | AL29: RES_KL3_FUR_FREEZE_COOK | AM29: =AG29*Z29 -> 0 | AN29: =B29 -> 45299 | AO29: 2 | AQ29: 12063755 | AR29: 12061353 | AS29: 12061354 | AT29: 12068566 | AV29: 12068564 | AW29: 12062153 | AY29: 12068565
B30: 45299 | C30: 45317 | D30: =IF(B30="","",YEAR(B30)) -> 2024 | E30: =VLOOKUP($B30,Week!$A$1:$C$1462,2,0) -> Week2 | F30: =IF(B30="","",TEXT(B30,"[$-409]mmm")) -> Jan | G30: DRY2300596 | H30: USA | I30: CPFNW | J30: Bellisio Foods, Inc. | K30: Wonton ND+V | L30: Cooked Wonton | M30: Cooked Wonton ND No Egg with Pumpkin + Yu Choy Low sodium | N30: 082SJBW36005P00001 | O30: 308g*6c*6in | P30: 36 | Q30: 5 | R30: 0.0075 | S30: HC | T30: Salt | U30: Y3 | V30: 615 | W30: =2330-131-792-792 -> 615 | Y30: =(W30+X30)-V30 -> 0 | Z30: =IF(Y30<0,((V30*P30)-((W30+X30)*P30)),0) -> 0 | AG30: =MID(O30,1,3)/1000 -> 0.308 | AH30: =(Z30*AG30)/1000 -> 0 | AI30: =V30*P30 -> 22140 | AK30: 66S03 | AL30: RES_KL3_FUR_FREEZE_COOK | AM30: =AG30*Z30 -> 0 | AN30: =B30 -> 45299 | AO30: 2 | AQ30: 12063755 | AR30: 12061353 | AS30: 12061354 | AT30: 12068566 | AV30: 12068564 | AW30: 12062153 | AY30: 12068565
A31: ชดเชยของกัก | B31: 45299 | C31: 45303 | D31: =IF(B31="","",YEAR(B31)) -> 2024 | E31: =VLOOKUP($B31,Week!$A$1:$C$1462,2,0) -> Week2 | F31: =IF(B31="","",TEXT(B31,"[$-409]mmm")) -> Jan | G31: DRY2300614 | H31: AUS | I31: CPFNW | J31: CPF Australia Pty Ltd. | K31: Wonton ND+V | L31: Cooked Wonton | M31: Cooked Wonton ND No Egg with Pumpkin + Yu Choy | N31: 082SJ9U36005P00001 | O31: 308g*6c*6in | P31: 36 | Q31: 5 | R31: 0.0075 | S31: HC | T31: Salt | U31: Regular | V31: 792 | W31: 792 | Y31: =(W31+X31)-V31 -> 0 | Z31: =IF(Y31<0,((V31*P31)-((W31+X31)*P31)),0) -> 0 | AG31: =MID(O31,1,3)/1000 -> 0.308 | AH31: =(Z31*AG31)/1000 -> 0 | AI31: =V31*P31 -> 28512 | AK31: 66S03 | AL31: RES_KL3_FUR_FREEZE_COOK | AM31: =AG31*Z31 -> 0 | AN31: =B31 -> 45299 | AO31: 2 | AP31: 4/1/22 | AQ31: 12063755 | AR31: 12061353 | AS31: 12061354 | AT31: 12062266 | AV31: 12062261 | AW31: 12062153 | AY31: 12062262
A32: ชดเชยของกัก | B32: 45299 | C32: 45309 | D32: =IF(B32="","",YEAR(B32)) -> 2024 | E32: =VLOOKUP($B32,Week!$A$1:$C$1462,2,0) -> Week2 | F32: =IF(B32="","",TEXT(B32,"[$-409]mmm")) -> Jan | G32: DRY2300615 | H32: AUS | I32: CPFNW | J32: CPF Australia Pty Ltd. | K32: Wonton ND+V | L32: Cooked Wonton | M32: Cooked Wonton ND No Egg with Pumpkin + Yu Choy | N32: 082SJ9U36005P00001 | O32: 308g*6c*6in | P32: 36 | Q32: 5 | R32: 0.0075 | S32: HC | T32: Salt | U32: Regular | V32: 792 | W32: =1086-792 -> 294 | X32: =(17928)/36 -> 498 | Y32: =(W32+X32)-V32 -> 0 | Z32: =IF(Y32<0,((V32*P32)-((W32+X32)*P32)),0) -> 0 | AG32: =MID(O32,1,3)/1000 -> 0.308 | AH32: =(Z32*AG32)/1000 -> 0 | AI32: =V32*P32 -> 28512 | AK32: 66S03 | AL32: RES_KL3_FUR_FREEZE_COOK | AM32: =AG32*Z32 -> 0 | AN32: =B32 -> 45299 | AO32: 2 | AP32: 4/1/22 | AQ32: 12063755 | AR32: 12061353 | AS32: 12061354 | AT32: 12062266 | AV32: 12062261 | AW32: 12062153 | AY32: 12062262
A33: R | B33: 45299 | C33: 45330 | D33: =IF(B33="","",YEAR(B33)) -> 2024 | E33: =VLOOKUP($B33,Week!$A$1:$C$1462,2,0) -> Week2 | F33: =IF(B33="","",TEXT(B33,"[$-409]mmm")) -> Jan | G33: KL2300038 | H33: China | I33: China | J33: Charoen Pokphand Import&Export Trading (Shanghai) Co., Ltd | K33: R-Wonton no egg | L33: Raw Wonton | M33: Raw Wonton 12 pcs | N33: 082I95J20012P04001 | O33: 144g*20in | P33: 20 | Q33: 12 | R33: 0.00681 | S33: S | T33: STPP | U33: ซุปซอง 5g. | V33: 1282 | W33: =1282 -> 1282 | Y33: =(W33+X33)-V33 -> 0 | Z33: =IF(Y33<0,((V33*P33)-((W33+X33)*P33)),0) -> 0 | AA33: =Q33*Z33 -> 0 | AB33: 2 | AC33: =Z33*AB33 -> 0 | AG33: =MID(O33,1,3)/1000 -> 0.144 | AH33: =(Z33*AG33)/1000 -> 0 | AI33: =V33*P33 -> 25640 | AK33: 66S03 | AL33: RES_KL3_FUR_FREEZE_RAW | AM33: =AG33*Z33 -> 0 | AN33: =B33 -> 45299 | AO33: 2 | AQ33: 12071839 | AR33: 12019692 | AT33: 12026905 | AV33: 12027007 | AX33: 12045309(248)
B34: 45300 | C34: 45324 | D34: =IF(B34="","",YEAR(B34)) -> 2024 | E34: =VLOOKUP($B34,Week!$A$1:$C$1462,2,0) -> Week2 | F34: =IF(B34="","",TEXT(B34,"[$-409]mmm")) -> Jan | G34: DRY2300678 | H34: USA | I34: CPFNW | J34: Bellisio Foods, Inc. | K34: Minced WT | L34: Cooked Wonton | M34: Cooked Minced Wonton No Egg | N34: 082SKBW08005P00001 | O34: 145g*8 | P34: 8 | Q34: 5 | R34: 0.006 | S34: BK | T34: Salt | U34: Regular | V34: =1400 -> 1400 | X34: =(1607+9593)/8 -> 1400 | Y34: =(W34+X34)-V34 -> 0 | Z34: =IF(Y34<0,((V34*P34)-((W34+X34)*P34)),0) -> 0 | AG34: =MID(O34,1,3)/1000 -> 0.145 | AH34: 0.26622 | AI34: =V34*P34 -> 11200 | AK34: 66S03 | AL34: RES_KL3_FUR_FREEZE_COOK | AM34: =AG34*Z34 -> 0 | AN34: =B34 -> 45300 | AO34: 2 | AP34: 8/12/21 | AQ34: 12071839 | AR34: 12047514 | AS34: 12047515 | AT34: 12083107 | AV34: 12084002
B35: 45300 | C35: 45335 | D35: =IF(B35="","",YEAR(B35)) -> 2024 | E35: =VLOOKUP($B35,Week!$A$1:$C$1462,2,0) -> Week2 | F35: =IF(B35="","",TEXT(B35,"[$-409]mmm")) -> Jan | G35: DRY2300725 | H35: USA | I35: CPFNW | J35: Bellisio Foods, Inc. | K35: Minced WT | L35: Cooked Wonton | M35: Cooked Minced Wonton No Egg | N35: 082SKBW08005P00001 | O35: 145g*8 | P35: 8 | Q35: 5 | R35: 0.006 | S35: BK | T35: Salt | U35: Regular | V35: =1400 -> 1400 | X35: =(11200)/8 -> 1400 | Y35: =(W35+X35)-V35 -> 0 | Z35: =IF(Y35<0,((V35*P35)-((W35+X35)*P35)),0) -> 0 | AG35: =MID(O35,1,3)/1000 -> 0.145 | AH35: 0.26622 | AI35: =V35*P35 -> 11200 | AK35: 66S03 | AL35: RES_KL3_FUR_FREEZE_COOK | AM35: =AG35*Z35 -> 0 | AN35: =B35 -> 45300 | AO35: 2 | AP35: 8/12/21 | AQ35: 12071839 | AR35: 12047514 | AS35: 12047515 | AT35: 12083107 | AV35: 12084002
B36: 45300 | C36: 45342 | D36: =IF(B36="","",YEAR(B36)) -> 2024 | E36: =VLOOKUP($B36,Week!$A$1:$C$1462,2,0) -> Week2 | F36: =IF(B36="","",TEXT(B36,"[$-409]mmm")) -> Jan | G36: DRY2300726 | H36: USA | I36: CPFNW | J36: Bellisio Foods, Inc. | K36: Minced WT | L36: Cooked Wonton | M36: Cooked Minced Wonton No Egg | N36: 082SKBW08005P00001 | O36: 145g*8 | P36: 8 | Q36: 5 | R36: 0.006 | S36: BK | T36: Salt | U36: Regular | V36: =700 -> 700 | X36: =(5600)/8 -> 700 | Y36: =(W36+X36)-V36 -> 0 | Z36: =IF(Y36<0,((V36*P36)-((W36+X36)*P36)),0) -> 0 | AG36: =MID(O36,1,3)/1000 -> 0.145 | AH36: 0.26622 | AI36: =V36*P36 -> 5600 | AK36: 66S03 | AL36: RES_KL3_FUR_FREEZE_COOK | AM36: =AG36*Z36 -> 0 | AN36: =B36 -> 45300 | AO36: 2 | AP36: 8/12/21 | AQ36: 12071839 | AR36: 12047514 | AS36: 12047515 | AT36: 12083107 | AV36: 12084002
B37: 45300 | C37: 45317 | D37: =IF(B37="","",YEAR(B37)) -> 2024 | E37: =VLOOKUP($B37,Week!$A$1:$C$1462,2,0) -> Week2 | F37: =IF(B37="","",TEXT(B37,"[$-409]mmm")) -> Jan | G37: DRY2300596 | H37: USA | I37: CPFNW | J37: Bellisio Foods, Inc. | K37: Wonton ND+V | L37: Cooked Wonton | M37: Cooked Wonton ND No Egg with Pumpkin + Yu Choy Low sodium | N37: 082SJBW36005P00001 | O37: 308g*6c*6in | P37: 36 | Q37: 5 | R37: 0.0075 | S37: HC | T37: Salt | U37: Y3 | V37: =792-615 -> 177 | W37: 177 | Y37: =(W37+X37)-V37 -> 0 | Z37: =IF(Y37<0,((V37*P37)-((W37+X37)*P37)),0) -> 0 | AG37: =MID(O37,1,3)/1000 -> 0.308 | AH37: =(Z37*AG37)/1000 -> 0 | AI37: =V37*P37 -> 6372 | AK37: 66S03 | AL37: RES_KL3_FUR_FREEZE_COOK | AM37: =AG37*Z37 -> 0 | AN37: =B37 -> 45300 | AO37: 2 | AQ37: 12063755 | AR37: 12061353 | AS37: 12061354 | AT37: 12068566 | AV37: 12068564 | AW37: 12062153 | AY37: 12068565
B38: 45300 | C38: 45317 | D38: =IF(B38="","",YEAR(B38)) -> 2024 | E38: =VLOOKUP($B38,Week!$A$1:$C$1462,2,0) -> Week2 | F38: =IF(B38="","",TEXT(B38,"[$-409]mmm")) -> Jan | G38: DRY2300607 | H38: USA | I38: CPFNW | J38: Bellisio Foods, Inc. | K38: Wonton ND+V | L38: Cooked Wonton | M38: Cooked Wonton ND No Egg with Pumpkin + Yu Choy Low sodium | N38: 082SJBW36005P00001 | O38: 308g*6c*6in | P38: 36 | Q38: 5 | R38: 0.0075 | S38: HC | T38: Salt | U38: Y3 | V38: 792 | W38: 792 | Y38: =(W38+X38)-V38 -> 0 | Z38: =IF(Y38<0,((V38*P38)-((W38+X38)*P38)),0) -> 0 | AG38: =MID(O38,1,3)/1000 -> 0.308 | AH38: =(Z38*AG38)/1000 -> 0 | AI38: =V38*P38 -> 28512 | AK38: 66S03 | AL38: RES_KL3_FUR_FREEZE_COOK | AM38: =AG38*Z38 -> 0 | AN38: =B38 -> 45300 | AO38: 2 | AQ38: 12063755 | AR38: 12061353 | AS38: 12061354 | AT38: 12068566 | AV38: 12068564 | AW38: 12062153 | AY38: 12068565
B39: 45300 | C39: 45317 | D39: =IF(B39="","",YEAR(B39)) -> 2024 | E39: =VLOOKUP($B39,Week!$A$1:$C$1462,2,0) -> Week2 | F39: =IF(B39="","",TEXT(B39,"[$-409]mmm")) -> Jan | G39: DRY2300601 | H39: USA | I39: CPFNW | J39: Bellisio Foods, Inc. | K39: Wonton ND+V | L39: Cooked Wonton | M39: Cooked Wonton ND No Egg with Pumpkin + Yu Choy Low sodium | N39: 082SJBW36005P00001 | O39: 308g*6c*6in | P39: 36 | Q39: 5 | R39: 0.0075 | S39: HC | T39: Salt | U39: Y3 | V39: 792 | W39: 792 | Y39: =(W39+X39)-V39 -> 0 | Z39: =IF(Y39<0,((V39*P39)-((W39+X39)*P39)),0) -> 0 | AG39: =MID(O39,1,3)/1000 -> 0.308 | AH39: =(Z39*AG39)/1000 -> 0 | AI39: =V39*P39 -> 28512 | AK39: 66S03 | AL39: RES_KL3_FUR_FREEZE_COOK | AM39: =AG39*Z39 -> 0 | AN39: =B39 -> 45300 | AO39: 2 | AQ39: 12063755 | AR39: 12061353 | AS39: 12061354 | AT39: 12068566 | AV39: 12068564 | AW39: 12062153 | AY39: 12068565
B40: 45300 | C40: 45317 | D40: =IF(B40="","",YEAR(B40)) -> 2024 | E40: =VLOOKUP($B40,Week!$A$1:$C$1462,2,0) -> Week2 | F40: =IF(B40="","",TEXT(B40,"[$-409]mmm")) -> Jan | G40: DRY2300602 | H40: USA | I40: CPFNW | J40: Bellisio Foods, Inc. | K40: Wonton ND+V | L40: Cooked Wonton | M40: Cooked Wonton ND No Egg with Pumpkin + Yu Choy Low sodium | N40: 082SJBW36005P00001 | O40: 308g*6c*6in | P40: 36 | Q40: 5 | R40: 0.0075 | S40: HC | T40: Salt | U40: Y3 | V40: 792 | W40: 792 | Y40: =(W40+X40)-V40 -> 0 | Z40: =IF(Y40<0,((V40*P40)-((W40+X40)*P40)),0) -> 0 | AG40: =MID(O40,1,3)/1000 -> 0.308 | AH40: =(Z40*AG40)/1000 -> 0 | AI40: =V40*P40 -> 28512 | AK40: 66S03 | AL40: RES_KL3_FUR_FREEZE_COOK | AM40: =AG40*Z40 -> 0 | AN40: =B40 -> 45300 | AO40: 2 | AQ40: 12063755 | AR40: 12061353 | AS40: 12061354 | AT40: 12068566 | AV40: 12068564 | AW40: 12062153 | AY40: 12068565
...

Sheet Sheet2
C1: CIP | D1: COP | E1: เตรียมไลน์ ต้มน้ำ ทำความเย็น | F1: ผลิต | G1: cap / Hr | I1: เดิมวางไว้ | J1: Dif
B2: 46041 | C2: 6 | D2: 8 | E2: 2 | F2: 14 | G2: =8300 -> 8300 | H2: =F2*G2 -> 116200 | I2: =140000 -> 140000 | J2: =H2-I2 -> -23800
B3: 46042 | C3: 6 | D3: 8 | E3: 2 | F3: 14 | G3: =8300 -> 8300 | H3: =F3*G3 -> 116200 | I3: =140000 -> 140000 | J3: =H3-I3 -> -23800
B4: 46043 | C4: 6 | D4: 8 | E4: 2 | F4: 14 | G4: =8300 -> 8300 | H4: =74784 -> 74784 | I4: =140000 -> 140000 | J4: =H4-I4 -> -65216
B5: 46044 | C5: 6 | D5: 8 | E5: 2 | F5: 14 | G5: =8300 -> 8300 | H5: =74784 -> 74784 | I5: =140000 -> 140000 | J5: =H5-I5 -> -65216
B6: 46045 | C6: 6 | D6: 8 | E6: 2 | F6: 14 | G6: =8300 -> 8300 | H6: =74784 -> 74784 | I6: =140000 -> 140000 | J6: =H6-I6 -> -65216
B7: 46046 | C7: 6 | D7: 8 | E7: 2 | F7: 14 | G7: =8300 -> 8300 | H7: =F7*G7 -> 116200 | I7: =140000 -> 140000 | J7: =H7-I7 -> -23800
C8: รวม 2 กิจกรรม 8 ชม.
G9: รวม | H9: =SUM(H2:H8) -> 572952 | I9: =SUM(I2:I8) -> 840000 | J9: =SUM(J2:J8) -> -267048
B11: หลังจากวีคนี้ สุก2กะ | C11: 6 | D11: 8 | E11: 2 | F11: 14 | G11: =8300 -> 8300 | H11: =F11*G11 -> 116200 | I11: =140000 -> 140000 | J11: =H11-I11 -> -23800
B13: หลังจากวีคนี้ สุก1กะ/ดิบ 1กะ | C13: 6 | D13: 8 | E13: 2 | F13: 10 | G13: =8300 -> 8300 | H13: =F13*G13 -> 83000 | I13: =83000 -> 83000 | J13: =H13-I13 -> 0
B14: สินค้าที่เข้ามาใหม่ทำให้ใช้ CAP ที่มีมากกว่าสินค้าอื่น เส้นมันหมาล่า เย็นตาโฟ ขี้เมาUK

Sheet RM & PD
B3: Column Labels | Q3: Raw Wonton | U3: Cooked Wonton
B4: Sum of WT/ PD | H4: Sum of WT/ HO | N4: Total Sum of WT/ PD | O4: Total Sum of WT/ HO
A5: Row Labels | B5: BK | C5: HC | D5: JB | E5: M | F5: S | G5: SS | H5: BK | I5: HC | J5: JB | K5: M | L5: S | M5: SS | Q5: Group2 | R5: Raw Wonton | U5: Group2 | V5: Cooked Wonton
A6: 2024 | S6: =300000 -> 300000 | T6: จำนวนกะ | W6: =8300*8 -> 66400 | X6: จำนวนกะ | Y6: รวมจำนวนกะ
A7: 2025 | B7: 0.000864 | C7: 0 | D7: 0 | E7: 7.2e-05 | F7: 0.00196128 | G7: 0 | H7: 0.0016 | I7: 0 | J7: 0 | K7: 0.00013333333 | L7: 0.003632 | M7: 0 | N7: 0.00289728 | O7: 0.0053653333 | Q7: Date | R7: short inner | S7: short PCS. | U7: Date | V7: short cup | W7: short PCS.
A8: 2026 | Q8: 2026 | U8: 2026
A9: Jan | B9: 0 | C9: 0 | E9: 0 | F9: 0 | G9: 0 | H9: 0 | I9: 0 | K9: 0 | L9: 0 | M9: 0 | N9: 0 | O9: 0 | Q9: Jan | R9: 0 | S9: 0 | U9: Jan | V9: 0 | W9: 0
A10: Feb | B10: 0 | C10: 0 | D10: 0 | E10: 0 | F10: 0 | G10: 0 | H10: 0 | I10: 0 | J10: 0 | K10: 0 | L10: 0 | M10: 0 | N10: 0 | O10: 0 | Q10: Feb | R10: 0 | S10: 0 | U10: Feb | V10: 0 | W10: 0
A11: Mar | B11: 0 | C11: 0 | D11: 0 | E11: 0 | F11: 0 | G11: 0 | H11: 0 | I11: 0 | J11: 0 | K11: 0 | L11: 0 | M11: 0 | N11: 0 | O11: 0 | Q11: Mar | R11: 0 | S11: 0 | U11: Mar | V11: 0 | W11: 0
A12: Apr | B12: 0 | C12: 0 | D12: 0 | E12: 0 | F12: 0 | G12: 0 | H12: 0 | I12: 0 | J12: 0 | K12: 0 | L12: 0 | M12: 0 | N12: 0 | O12: 0 | Q12: Apr | R12: 0 | S12: 0 | U12: Apr | V12: 0 | W12: 0
A13: May | B13: 0 | C13: 0 | D13: 0 | E13: 0 | F13: 0 | G13: 0 | H13: 0 | I13: 0 | J13: 0 | K13: 0 | L13: 0 | M13: 0 | N13: 0 | O13: 0 | Q13: May | R13: 0 | S13: 0 | U13: May | V13: 0 | W13: 0
A14: Jun | B14: 0 | C14: 0 | E14: 0 | F14: 0 | G14: 0 | H14: 0 | I14: 0 | K14: 0 | L14: 0 | M14: 0 | N14: 0 | O14: 0 | Q14: Jun | R14: 0 | S14: 0 | U14: Jun | V14: 0 | W14: 0
A15: Jul | B15: 0 | C15: 0 | D15: 0 | E15: 0 | F15: 0 | G15: 0 | H15: 0 | I15: 0 | J15: 0 | K15: 0 | L15: 0 | M15: 0 | N15: 0 | O15: 0 | Q15: Jul | R15: 0 | S15: 0 | U15: Jul | V15: 0 | W15: 0
A16: Aug | B16: 0.033948 | C16: 0 | E16: 0 | F16: 0 | G16: 0 | H16: 0.062866667 | I16: 0 | K16: 0 | L16: 0 | M16: 0 | N16: 0.033948 | O16: 0.062866667 | Q16: Aug | R16: 0 | S16: 0 | T16: =GETPIVOTDATA("short PCS.",$Q$7,"year",2026,"Month","Aug")/S6 -> 0 | U16: Aug | V16: 1886 | W16: 5658 | X16: =GETPIVOTDATA("short cup",$U$7,"year",2026,"Month","Aug")/W6 -> 0.028403614 | Y16: =T16+X16 -> 0.028403614
A17: Sep | B17: 5.1198444 | C17: 17.401103 | E17: 16.151322 | F17: 10.35801 | G17: 9.3577344 | H17: 9.4811933 | I17: 32.224264 | K17: 29.909855 | L17: 19.1815 | M17: 17.329138 | N17: 58.388013 | O17: 108.12595 | Q17: Sep | R17: 93380 | S17: 1897320 | T17: =GETPIVOTDATA("short PCS.",$Q$7,"year",2026,"Month","Sep")/S6 -> 6.3244 | U17: Sep | V17: 1383460 | W17: 6396617 | X17: =GETPIVOTDATA("short cup",$U$7,"year",2026,"Month","Sep")/W6 -> 20.835241 | Y17: =T17+X17 -> 27.159641
A18: Oct | B18: 3.35556 | C18: 14.6934 | E18: 36.487608 | F18: 17.727792 | G18: 25.317456 | H18: 6.214 | I18: 27.21 | K18: 67.569644 | L18: 32.829244 | M18: 46.884178 | N18: 97.581816 | O18: 180.70707 | Q18: Oct | R18: 220120 | S18: 3968800 | T18: =GETPIVOTDATA("short PCS.",$Q$7,"year",2026,"Month","Oct")/S6 -> 13.229333 | U18: Oct | V18: 2034660 | W18: 9745920 | X18: =GETPIVOTDATA("short cup",$U$7,"year",2026,"Month","Oct")/W6 -> 30.64247 | Y18: =T18+X18 -> 43.871803
A19: Nov | B19: 2.535024 | H19: 4.6944889 | N19: 2.535024 | O19: 4.6944889 | Q19: Dec | R19: 257980 | S19: 3177360 | T19: =GETPIVOTDATA("short PCS.",$Q$7,"year",2026,"Month","Dec")/S6 -> 10.5912 | U19: Nov | V19: 108760 | W19: 416120 | X19: =GETPIVOTDATA("short cup",$U$7,"year",2026,"Month","Nov")/W6 -> 1.6379518 | Y19: =T19+X19 -> 12.229152
A20: Dec | B20: 4.75704 | C20: 6.4056 | E20: 33.280169 | F20: 4.396536 | G20: 10.37136 | H20: 8.8093333 | I20: 11.862222 | K20: 61.629942 | L20: 8.1417333 | M20: 19.206222 | N20: 59.210705 | O20: 109.64945 | Q20: 2027 | U20: Dec | V20: 1049696 | W20: 4989368 | X20: =GETPIVOTDATA("short cup",$U$7,"year",2026,"Month","Dec")/W6 -> 15.808675 | Y20: =T20+X20 -> 15.808675
A21: 2027 | Q21: Jan | R21: 433196 | S21: 5681168 | T21: =GETPIVOTDATA("short PCS.",$Q$7,"year",2027,"Month","Jan")/S6 -> 18.937227 | U21: 2027
A22: Jan | B22: 10.197624 | C22: 5.508 | D22: 5.76 | E22: 19.557658 | F22: 30.000284 | G22: 10.37136 | H22: 18.884489 | I22: 10.2 | J22: 10.666667 | K22: 36.217884 | L22: 55.556081 | M22: 19.206222 | N22: 81.394925 | O22: 150.73134 | Q22: Feb | R22: 25400 | S22: 283200 | T22: =GETPIVOTDATA("short PCS.",$Q$7,"year",2027,"Month","Feb")/S6 -> 0.944 | U22: Jan | V22: 1239292 | W22: 5635820 | X22: =GETPIVOTDATA("short cup",$U$7,"year",2027,"Month","Jan")/W6 -> 18.664036 | Y22: =T22+X22 -> 19.608036
A23: Feb | B23: 4.06188 | C23: 6.16524 | E23: 13.73628 | F23: 1.6344 | G23: 10.37136 | H23: 7.522 | I23: 11.417111 | K23: 25.437556 | L23: 3.0266667 | M23: 19.206222 | N23: 35.96916 | O23: 66.609556 | Q23: Grand Total | R23: 1030076 | S23: 15007848 | T23: =GETPIVOTDATA("short PCS.",$Q$7,"year",2027,"Month","Feb")/S6 -> 0.944 | U23: Feb | V23: 1038584 | W23: 4910572 | X23: =GETPIVOTDATA("short cup",$U$7,"year",2027,"Month","Feb")/W6 -> 15.641325 | Y23: =T23+X23 -> 16.585325
A24: Grand Total | B24: 30.061784 | C24: 50.173343 | D24: 5.76 | E24: 119.21311 | F24: 64.118983 | G24: 65.78927 | H24: 55.669971 | I24: 92.913597 | J24: 10.666667 | K24: 220.76501 | L24: 118.73886 | M24: 121.83198 | N24: 335.11649 | O24: 620.58609 | U24: Grand Total | V24: 6856338 | W24: 32100075

Sheet Sheet5
A3: Sum of KG
A4: แผนผลิต Date | B4: RM | C4: Total
A5: 46279 | B5: (blank)
A6: 46280 | B6: (blank)
A7: 46281 | B7: Aubergine | C7: 1518.6667
A8: 46282 | B8: BK | C8: 1333.3333
B9: S | C9: 2855.1556
B10: SS | C10: 1102.2222
A11: 46283 | B11: BK | C11: 1333.3333
B12: S | C12: 3450.4
A13: 46284 | B13: BK | C13: 1089.5467
B14: HC | C14: 1980
B15: M | C15: 3637.037
A16: 46285 | B16: BK | C16: 1045.1133
B17: HC | C17: 5940

Sheet Assortment
A1: =IF(A3>0,"Week "&WEEKNUM(A3,1)," ") -> Week 37 | C1: =IF(C3>0,"Week "&WEEKNUM(C3,1)," ") -> Week 37 | E1: =IF(E3>0,"Week "&WEEKNUM(E3,1)," ") -> Week 38 | G1: =IF(G3>0,"Week "&WEEKNUM(G3,1)," ") -> Week 38 | I1: =IF(I3>0,"Week "&WEEKNUM(I3,1)," ") -> Week 38 | K1: =IF(K3>0,"Week "&WEEKNUM(K3,1)," ") -> Week 38
A3: 46275 | B3: =TEXT(B4,"ddd") -> พฤ. | C3: 46276 | D3: =TEXT(D4,"ddd") -> ศ. | E3: 46279 | F3: =TEXT(F4,"ddd") -> จ. | G3: 46280 | H3: =TEXT(H4,"ddd") -> อ. | I3: 46280 | J3: =TEXT(J4,"ddd") -> อ. | K3: 46281 | L3: =TEXT(L4,"ddd") -> พ. | M3: 46282 | N3: =TEXT(N4,"ddd") -> พฤ. | O3: Total
A4: วันที่ | B4: =A3 -> 46275 | C4: วันที่ | D4: =C3 -> 46276 | E4: วันที่ | F4: =E3 -> 46279 | G4: วันที่ | H4: =G3 -> 46280 | I4: วันที่ | J4: =I3 -> 46280 | K4: วันที่ | L4: =K3 -> 46281 | M4: วันที่ | N4: =M3 -> 46282
A5: ฟาร์ม | B5: ณรรฐพงษ์ฟาร์ม (กีระติ บุญนิมิตร) | C5: ฟาร์ม | D5: สิริชัย เลิศชัยพัฒนกุล | E5: ฟาร์ม | F5: ณรรฐพงษ์ฟาร์ม (กีระติ บุญนิมิตร) | G5: ฟาร์ม | H5: ลูกกระต่ายฟาร์ม-พัชรินทร์ จินดาพรรณ | I5: ฟาร์ม | J5: ลูกกระต่ายฟาร์ม-พัชรินทร์ จินดาพรรณ | K5: ฟาร์ม | L5: ลูกกระต่ายฟาร์ม-พัชรินทร์ จินดาพรรณ | M5: ฟาร์ม | N5: ลูกกระต่ายฟาร์ม-พัชรินทร์ จินดาพรรณ
A6: จังหวัด | B6: จันทบุรี | C6: จังหวัด | D6: ตราด | E6: จังหวัด | F6: จันทบุรี | G6: จังหวัด | H6: จันทบุรี | I6: จังหวัด | J6: จันทบุรี | K6: จังหวัด | L6: จันทบุรี | M6: จังหวัด | N6: จันทบุรี
A7: บ่อ | C7: บ่อ | E7: บ่อ | G7: บ่อ | I7: บ่อ | K7: บ่อ | M7: บ่อ
A8: size | B8: 80 | C8: size | D8: 80 | E8: size | F8: 80 | G8: size | H8: 80 | I8: size | J8: 80 | K8: size | L8: 80 | M8: size | N8: 80
A9: การจับ | B9: Closed | C9: การจับ | D9: Closed | E9: การจับ | F9: Closed | G9: การจับ | H9: Closed | I9: การจับ | J9: Closed | K9: การจับ | L9: Closed | M9: การจับ | N9: Closed
A10: ปริมาณ(กก.) | B10: 6000 | C10: ปริมาณ(กก.) | D10: 5500 | E10: ปริมาณ(กก.) | F10: 6000 | G10: ปริมาณ(กก.) | H10: 5000 | I10: ปริมาณ(กก.) | J10: 5000 | K10: ปริมาณ(กก.) | L10: 5000 | M10: ปริมาณ(กก.) | N10: 5000 | U10: Category
A11: 46-50 | B11: =IFERROR($B$10*INDEX([2]Master!$B$3:$T$21,MATCH($A11,[2]Master!$A$3:$A$21,0),MATCH("S."&B$8,[2]Master!$B$2:$T$2,0)),0) -> 0 | C11: 46-50 | D11: =IFERROR($D$10*INDEX([2]Master!$B$3:$T$21,MATCH($A11,[2]Master!$A$3:$A$21,0),MATCH("S."&D$8,[2]Master!$B$2:$T$2,0)),0) -> 0 | E11: 46-50 | F11: =IFERROR($F$10*INDEX([2]Master!$B$3:$T$21,MATCH($A11,[2]Master!$A$3:$A$21,0),MATCH("S."&F$8,[2]Master!$B$2:$T$2,0)),0) -> 0 | G11: 46-50 | H11: =IFERROR($H$10*INDEX([2]Master!$B$3:$T$21,MATCH($A11,[2]Master!$A$3:$A$21,0),MATCH("S."&H$8,[2]Master!$B$2:$T$2,0)),0) -> 0 | I11: 46-50 | J11: =IFERROR($J$10*INDEX([2]Master!$B$3:$T$21,MATCH($A11,[2]Master!$A$3:$A$21,0),MATCH("S."&J$8,[2]Master!$B$2:$T$2,0)),0) -> 0 | K11: 46-50 | L11: =IFERROR($J$10*INDEX([2]Master!$B$3:$T$21,MATCH($A11,[2]Master!$A$3:$A$21,0),MATCH("S."&L$8,[2]Master!$B$2:$T$2,0)),0) -> 0 | M11: 46-50 | N11: =IFERROR($J$10*INDEX([2]Master!$B$3:$T$21,MATCH($A11,[2]Master!$A$3:$A$21,0),MATCH("S."&N$8,[2]Master!$B$2:$T$2,0)),0) -> 0 | O11: =SUM(B11:N11) -> 0
A12: 51-55 | B12: =IFERROR($B$10*INDEX([2]Master!$B$3:$T$21,MATCH($A12,[2]Master!$A$3:$A$21,0),MATCH("S."&B$8,[2]Master!$B$2:$T$2,0)),0) -> 213.7883 | C12: 51-55 | D12: =IFERROR($D$10*INDEX([2]Master!$B$3:$T$21,MATCH($A12,[2]Master!$A$3:$A$21,0),MATCH("S."&D$8,[2]Master!$B$2:$T$2,0)),0) -> 195.97261 | E12: 51-55 | F12: =IFERROR($F$10*INDEX([2]Master!$B$3:$T$21,MATCH($A12,[2]Master!$A$3:$A$21,0),MATCH("S."&F$8,[2]Master!$B$2:$T$2,0)),0) -> 213.7883 | G12: 51-55 | H12: =IFERROR($H$10*INDEX([2]Master!$B$3:$T$21,MATCH($A12,[2]Master!$A$3:$A$21,0),MATCH("S."&H$8,[2]Master!$B$2:$T$2,0)),0) -> 178.15692 | I12: 51-55 | J12: =IFERROR($J$10*INDEX([2]Master!$B$3:$T$21,MATCH($A12,[2]Master!$A$3:$A$21,0),MATCH("S."&J$8,[2]Master!$B$2:$T$2,0)),0) -> 178.15692 | K12: 51-55 | L12: =IFERROR($J$10*INDEX([2]Master!$B$3:$T$21,MATCH($A12,[2]Master!$A$3:$A$21,0),MATCH("S."&L$8,[2]Master!$B$2:$T$2,0)),0) -> 178.15692 | M12: 51-55 | N12: =IFERROR($J$10*INDEX([2]Master!$B$3:$T$21,MATCH($A12,[2]Master!$A$3:$A$21,0),MATCH("S."&N$8,[2]Master!$B$2:$T$2,0)),0) -> 178.15692 | O12: =SUM(B12:N12) -> 1336.1769 | U12: M
A13: 56-60 | B13: =IFERROR($B$10*INDEX([2]Master!$B$3:$T$21,MATCH($A13,[2]Master!$A$3:$A$21,0),MATCH("S."&B$8,[2]Master!$B$2:$T$2,0)),0) -> 242.37378 | C13: 56-60 | D13: =IFERROR($D$10*INDEX([2]Master!$B$3:$T$21,MATCH($A13,[2]Master!$A$3:$A$21,0),MATCH("S."&D$8,[2]Master!$B$2:$T$2,0)),0) -> 222.17596 | E13: 56-60 | F13: =IFERROR($F$10*INDEX([2]Master!$B$3:$T$21,MATCH($A13,[2]Master!$A$3:$A$21,0),MATCH("S."&F$8,[2]Master!$B$2:$T$2,0)),0) -> 242.37378 | G13: 56-60 | H13: =IFERROR($H$10*INDEX([2]Master!$B$3:$T$21,MATCH($A13,[2]Master!$A$3:$A$21,0),MATCH("S."&H$8,[2]Master!$B$2:$T$2,0)),0) -> 201.97815 | I13: 56-60 | J13: =IFERROR($J$10*INDEX([2]Master!$B$3:$T$21,MATCH($A13,[2]Master!$A$3:$A$21,0),MATCH("S."&J$8,[2]Master!$B$2:$T$2,0)),0) -> 201.97815 | K13: 56-60 | L13: =IFERROR($J$10*INDEX([2]Master!$B$3:$T$21,MATCH($A13,[2]Master!$A$3:$A$21,0),MATCH("S."&L$8,[2]Master!$B$2:$T$2,0)),0) -> 201.97815 | M13: 56-60 | N13: =IFERROR($J$10*INDEX([2]Master!$B$3:$T$21,MATCH($A13,[2]Master!$A$3:$A$21,0),MATCH("S."&N$8,[2]Master!$B$2:$T$2,0)),0) -> 201.97815 | O13: =SUM(B13:N13) -> 1514.8361 | U13: M
A14: 61-65 | B14: =IFERROR($B$10*INDEX([2]Master!$B$3:$T$21,MATCH($A14,[2]Master!$A$3:$A$21,0),MATCH("S."&B$8,[2]Master!$B$2:$T$2,0)),0) -> 51.290888 | C14: 61-65 | D14: =IFERROR($D$10*INDEX([2]Master!$B$3:$T$21,MATCH($A14,[2]Master!$A$3:$A$21,0),MATCH("S."&D$8,[2]Master!$B$2:$T$2,0)),0) -> 47.016647 | E14: 61-65 | F14: =IFERROR($F$10*INDEX([2]Master!$B$3:$T$21,MATCH($A14,[2]Master!$A$3:$A$21,0),MATCH("S."&F$8,[2]Master!$B$2:$T$2,0)),0) -> 51.290888 | G14: 61-65 | H14: =IFERROR($H$10*INDEX([2]Master!$B$3:$T$21,MATCH($A14,[2]Master!$A$3:$A$21,0),MATCH("S."&H$8,[2]Master!$B$2:$T$2,0)),0) -> 42.742406 | I14: 61-65 | J14: =IFERROR($J$10*INDEX([2]Master!$B$3:$T$21,MATCH($A14,[2]Master!$A$3:$A$21,0),MATCH("S."&J$8,[2]Master!$B$2:$T$2,0)),0) -> 42.742406 | K14: 61-65 | L14: =IFERROR($J$10*INDEX([2]Master!$B$3:$T$21,MATCH($A14,[2]Master!$A$3:$A$21,0),MATCH("S."&L$8,[2]Master!$B$2:$T$2,0)),0) -> 42.742406 | M14: 61-65 | N14: =IFERROR($J$10*INDEX([2]Master!$B$3:$T$21,MATCH($A14,[2]Master!$A$3:$A$21,0),MATCH("S."&N$8,[2]Master!$B$2:$T$2,0)),0) -> 42.742406 | O14: =SUM(B14:N14) -> 320.56805 | U14: M
A15: 66-70 | B15: =IFERROR($B$10*INDEX([2]Master!$B$3:$T$21,MATCH($A15,[2]Master!$A$3:$A$21,0),MATCH("S."&B$8,[2]Master!$B$2:$T$2,0)),0) -> 2165.646 | C15: 66-70 | D15: =IFERROR($D$10*INDEX([2]Master!$B$3:$T$21,MATCH($A15,[2]Master!$A$3:$A$21,0),MATCH("S."&D$8,[2]Master!$B$2:$T$2,0)),0) -> 1985.1755 | E15: 66-70 | F15: =IFERROR($F$10*INDEX([2]Master!$B$3:$T$21,MATCH($A15,[2]Master!$A$3:$A$21,0),MATCH("S."&F$8,[2]Master!$B$2:$T$2,0)),0) -> 2165.646 | G15: 66-70 | H15: =IFERROR($H$10*INDEX([2]Master!$B$3:$T$21,MATCH($A15,[2]Master!$A$3:$A$21,0),MATCH("S."&H$8,[2]Master!$B$2:$T$2,0)),0) -> 1804.705 | I15: 66-70 | J15: =IFERROR($J$10*INDEX([2]Master!$B$3:$T$21,MATCH($A15,[2]Master!$A$3:$A$21,0),MATCH("S."&J$8,[2]Master!$B$2:$T$2,0)),0) -> 1804.705 | K15: 66-70 | L15: =IFERROR($J$10*INDEX([2]Master!$B$3:$T$21,MATCH($A15,[2]Master!$A$3:$A$21,0),MATCH("S."&L$8,[2]Master!$B$2:$T$2,0)),0) -> 1804.705 | M15: 66-70 | N15: =IFERROR($J$10*INDEX([2]Master!$B$3:$T$21,MATCH($A15,[2]Master!$A$3:$A$21,0),MATCH("S."&N$8,[2]Master!$B$2:$T$2,0)),0) -> 1804.705 | O15: =SUM(B15:N15) -> 13535.288 | U15: M
A16: 71-75 | B16: =IFERROR($B$10*INDEX([2]Master!$B$3:$T$21,MATCH($A16,[2]Master!$A$3:$A$21,0),MATCH("S."&B$8,[2]Master!$B$2:$T$2,0)),0) -> 191.4277 | C16: 71-75 | D16: =IFERROR($D$10*INDEX([2]Master!$B$3:$T$21,MATCH($A16,[2]Master!$A$3:$A$21,0),MATCH("S."&D$8,[2]Master!$B$2:$T$2,0)),0) -> 175.47539 | E16: 71-75 | F16: =IFERROR($F$10*INDEX([2]Master!$B$3:$T$21,MATCH($A16,[2]Master!$A$3:$A$21,0),MATCH("S."&F$8,[2]Master!$B$2:$T$2,0)),0) -> 191.4277 | G16: 71-75 | H16: =IFERROR($H$10*INDEX([2]Master!$B$3:$T$21,MATCH($A16,[2]Master!$A$3:$A$21,0),MATCH("S."&H$8,[2]Master!$B$2:$T$2,0)),0) -> 159.52308 | I16: 71-75 | J16: =IFERROR($J$10*INDEX([2]Master!$B$3:$T$21,MATCH($A16,[2]Master!$A$3:$A$21,0),MATCH("S."&J$8,[2]Master!$B$2:$T$2,0)),0) -> 159.52308 | K16: 71-75 | L16: =IFERROR($J$10*INDEX([2]Master!$B$3:$T$21,MATCH($A16,[2]Master!$A$3:$A$21,0),MATCH("S."&L$8,[2]Master!$B$2:$T$2,0)),0) -> 159.52308 | M16: 71-75 | N16: =IFERROR($J$10*INDEX([2]Master!$B$3:$T$21,MATCH($A16,[2]Master!$A$3:$A$21,0),MATCH("S."&N$8,[2]Master!$B$2:$T$2,0)),0) -> 159.52308 | O16: =SUM(B16:N16) -> 1196.4231 | U16: M
A17: 76-80 | B17: =IFERROR($B$10*INDEX([2]Master!$B$3:$T$21,MATCH($A17,[2]Master!$A$3:$A$21,0),MATCH("S."&B$8,[2]Master!$B$2:$T$2,0)),0) -> 1635.8885 | C17: 76-80 | D17: =IFERROR($D$10*INDEX([2]Master!$B$3:$T$21,MATCH($A17,[2]Master!$A$3:$A$21,0),MATCH("S."&D$8,[2]Master!$B$2:$T$2,0)),0) -> 1499.5644 | E17: 76-80 | F17: =IFERROR($F$10*INDEX([2]Master!$B$3:$T$21,MATCH($A17,[2]Master!$A$3:$A$21,0),MATCH("S."&F$8,[2]Master!$B$2:$T$2,0)),0) -> 1635.8885 | G17: 76-80 | H17: =IFERROR($H$10*INDEX([2]Master!$B$3:$T$21,MATCH($A17,[2]Master!$A$3:$A$21,0),MATCH("S."&H$8,[2]Master!$B$2:$T$2,0)),0) -> 1363.2404 | I17: 76-80 | J17: =IFERROR($J$10*INDEX([2]Master!$B$3:$T$21,MATCH($A17,[2]Master!$A$3:$A$21,0),MATCH("S."&J$8,[2]Master!$B$2:$T$2,0)),0) -> 1363.2404 | K17: 76-80 | L17: =IFERROR($J$10*INDEX([2]Master!$B$3:$T$21,MATCH($A17,[2]Master!$A$3:$A$21,0),MATCH("S."&L$8,[2]Master!$B$2:$T$2,0)),0) -> 1363.2404 | M17: 76-80 | N17: =IFERROR($J$10*INDEX([2]Master!$B$3:$T$21,MATCH($A17,[2]Master!$A$3:$A$21,0),MATCH("S."&N$8,[2]Master!$B$2:$T$2,0)),0) -> 1363.2404 | O17: =SUM(B17:N17) -> 10224.303 | U17: S/SS
A18: 81-85 | B18: =IFERROR($B$10*INDEX([2]Master!$B$3:$T$21,MATCH($A18,[2]Master!$A$3:$A$21,0),MATCH("S."&B$8,[2]Master!$B$2:$T$2,0)),0) -> 200.00608 | C18: 81-85 | D18: =IFERROR($D$10*INDEX([2]Master!$B$3:$T$21,MATCH($A18,[2]Master!$A$3:$A$21,0),MATCH("S."&D$8,[2]Master!$B$2:$T$2,0)),0) -> 183.33891 | E18: 81-85 | F18: =IFERROR($F$10*INDEX([2]Master!$B$3:$T$21,MATCH($A18,[2]Master!$A$3:$A$21,0),MATCH("S."&F$8,[2]Master!$B$2:$T$2,0)),0) -> 200.00608 | G18: 81-85 | H18: =IFERROR($H$10*INDEX([2]Master!$B$3:$T$21,MATCH($A18,[2]Master!$A$3:$A$21,0),MATCH("S."&H$8,[2]Master!$B$2:$T$2,0)),0) -> 166.67174 | I18: 81-85 | J18: =IFERROR($J$10*INDEX([2]Master!$B$3:$T$21,MATCH($A18,[2]Master!$A$3:$A$21,0),MATCH("S."&J$8,[2]Master!$B$2:$T$2,0)),0) -> 166.67174 | K18: 81-85 | L18: =IFERROR($J$10*INDEX([2]Master!$B$3:$T$21,MATCH($A18,[2]Master!$A$3:$A$21,0),MATCH("S."&L$8,[2]Master!$B$2:$T$2,0)),0) -> 166.67174 | M18: 81-85 | N18: =IFERROR($J$10*INDEX([2]Master!$B$3:$T$21,MATCH($A18,[2]Master!$A$3:$A$21,0),MATCH("S."&N$8,[2]Master!$B$2:$T$2,0)),0) -> 166.67174 | O18: =SUM(B18:N18) -> 1250.038 | U18: S/SS
A19: 86-90 | B19: =IFERROR($B$10*INDEX([2]Master!$B$3:$T$21,MATCH($A19,[2]Master!$A$3:$A$21,0),MATCH("S."&B$8,[2]Master!$B$2:$T$2,0)),0) -> 9.1759492 | C19: 86-90 | D19: =IFERROR($D$10*INDEX([2]Master!$B$3:$T$21,MATCH($A19,[2]Master!$A$3:$A$21,0),MATCH("S."&D$8,[2]Master!$B$2:$T$2,0)),0) -> 8.4112868 | E19: 86-90 | F19: =IFERROR($F$10*INDEX([2]Master!$B$3:$T$21,MATCH($A19,[2]Master!$A$3:$A$21,0),MATCH("S."&F$8,[2]Master!$B$2:$T$2,0)),0) -> 9.1759492 | G19: 86-90 | H19: =IFERROR($H$10*INDEX([2]Master!$B$3:$T$21,MATCH($A19,[2]Master!$A$3:$A$21,0),MATCH("S."&H$8,[2]Master!$B$2:$T$2,0)),0) -> 7.6466244 | I19: 86-90 | J19: =IFERROR($J$10*INDEX([2]Master!$B$3:$T$21,MATCH($A19,[2]Master!$A$3:$A$21,0),MATCH("S."&J$8,[2]Master!$B$2:$T$2,0)),0) -> 7.6466244 | K19: 86-90 | L19: =IFERROR($J$10*INDEX([2]Master!$B$3:$T$21,MATCH($A19,[2]Master!$A$3:$A$21,0),MATCH("S."&L$8,[2]Master!$B$2:$T$2,0)),0) -> 7.6466244 | M19: 86-90 | N19: =IFERROR($J$10*INDEX([2]Master!$B$3:$T$21,MATCH($A19,[2]Master!$A$3:$A$21,0),MATCH("S."&N$8,[2]Master!$B$2:$T$2,0)),0) -> 7.6466244 | O19: =SUM(B19:N19) -> 57.349683 | U19: S/SS
A20: 91-95 | B20: =IFERROR($B$10*INDEX([2]Master!$B$3:$T$21,MATCH($A20,[2]Master!$A$3:$A$21,0),MATCH("S."&B$8,[2]Master!$B$2:$T$2,0)),0) -> 792.09426 | C20: 91-95 | D20: =IFERROR($D$10*INDEX([2]Master!$B$3:$T$21,MATCH($A20,[2]Master!$A$3:$A$21,0),MATCH("S."&D$8,[2]Master!$B$2:$T$2,0)),0) -> 726.08641 | E20: 91-95 | F20: =IFERROR($F$10*INDEX([2]Master!$B$3:$T$21,MATCH($A20,[2]Master!$A$3:$A$21,0),MATCH("S."&F$8,[2]Master!$B$2:$T$2,0)),0) -> 792.09426 | G20: 91-95 | H20: =IFERROR($H$10*INDEX([2]Master!$B$3:$T$21,MATCH($A20,[2]Master!$A$3:$A$21,0),MATCH("S."&H$8,[2]Master!$B$2:$T$2,0)),0) -> 660.07855 | I20: 91-95 | J20: =IFERROR($J$10*INDEX([2]Master!$B$3:$T$21,MATCH($A20,[2]Master!$A$3:$A$21,0),MATCH("S."&J$8,[2]Master!$B$2:$T$2,0)),0) -> 660.07855 | K20: 91-95 | L20: =IFERROR($J$10*INDEX([2]Master!$B$3:$T$21,MATCH($A20,[2]Master!$A$3:$A$21,0),MATCH("S."&L$8,[2]Master!$B$2:$T$2,0)),0) -> 660.07855 | M20: 91-95 | N20: =IFERROR($J$10*INDEX([2]Master!$B$3:$T$21,MATCH($A20,[2]Master!$A$3:$A$21,0),MATCH("S."&N$8,[2]Master!$B$2:$T$2,0)),0) -> 660.07855 | O20: =SUM(B20:N20) -> 4950.5891 | U20: S/SS
A21: 96-100 | B21: =IFERROR($B$10*INDEX([2]Master!$B$3:$T$21,MATCH($A21,[2]Master!$A$3:$A$21,0),MATCH("S."&B$8,[2]Master!$B$2:$T$2,0)),0) -> 0 | C21: 96-100 | D21: =IFERROR($D$10*INDEX([2]Master!$B$3:$T$21,MATCH($A21,[2]Master!$A$3:$A$21,0),MATCH("S."&D$8,[2]Master!$B$2:$T$2,0)),0) -> 0 | E21: 96-100 | F21: =IFERROR($F$10*INDEX([2]Master!$B$3:$T$21,MATCH($A21,[2]Master!$A$3:$A$21,0),MATCH("S."&F$8,[2]Master!$B$2:$T$2,0)),0) -> 0 | G21: 96-100 | H21: =IFERROR($H$10*INDEX([2]Master!$B$3:$T$21,MATCH($A21,[2]Master!$A$3:$A$21,0),MATCH("S."&H$8,[2]Master!$B$2:$T$2,0)),0) -> 0 | I21: 96-100 | J21: =IFERROR($J$10*INDEX([2]Master!$B$3:$T$21,MATCH($A21,[2]Master!$A$3:$A$21,0),MATCH("S."&J$8,[2]Master!$B$2:$T$2,0)),0) -> 0 | K21: 96-100 | L21: =IFERROR($J$10*INDEX([2]Master!$B$3:$T$21,MATCH($A21,[2]Master!$A$3:$A$21,0),MATCH("S."&L$8,[2]Master!$B$2:$T$2,0)),0) -> 0 | M21: 96-100 | N21: =IFERROR($J$10*INDEX([2]Master!$B$3:$T$21,MATCH($A21,[2]Master!$A$3:$A$21,0),MATCH("S."&N$8,[2]Master!$B$2:$T$2,0)),0) -> 0 | O21: =SUM(B21:N21) -> 0 | U21: S/SS
A22: 101-120 | B22: =IFERROR($B$10*INDEX([2]Master!$B$3:$T$21,MATCH($A22,[2]Master!$A$3:$A$21,0),MATCH("S."&B$8,[2]Master!$B$2:$T$2,0)),0) -> 364.8049 | C22: 101-120 | D22: =IFERROR($D$10*INDEX([2]Master!$B$3:$T$21,MATCH($A22,[2]Master!$A$3:$A$21,0),MATCH("S."&D$8,[2]Master!$B$2:$T$2,0)),0) -> 334.40449 | E22: 101-120 | F22: =IFERROR($F$10*INDEX([2]Master!$B$3:$T$21,MATCH($A22,[2]Master!$A$3:$A$21,0),MATCH("S."&F$8,[2]Master!$B$2:$T$2,0)),0) -> 364.8049 | G22: 101-120 | H22: =IFERROR($H$10*INDEX([2]Master!$B$3:$T$21,MATCH($A22,[2]Master!$A$3:$A$21,0),MATCH("S."&H$8,[2]Master!$B$2:$T$2,0)),0) -> 304.00408 | I22: 101-120 | J22: =IFERROR($J$10*INDEX([2]Master!$B$3:$T$21,MATCH($A22,[2]Master!$A$3:$A$21,0),MATCH("S."&J$8,[2]Master!$B$2:$T$2,0)),0) -> 304.00408 | K22: 101-120 | L22: =IFERROR($J$10*INDEX([2]Master!$B$3:$T$21,MATCH($A22,[2]Master!$A$3:$A$21,0),MATCH("S."&L$8,[2]Master!$B$2:$T$2,0)),0) -> 304.00408 | M22: 101-120 | N22: =IFERROR($J$10*INDEX([2]Master!$B$3:$T$21,MATCH($A22,[2]Master!$A$3:$A$21,0),MATCH("S."&N$8,[2]Master!$B$2:$T$2,0)),0) -> 304.00408 | O22: =SUM(B22:N22) -> 2280.0306 | U22: Broken
A23: 121-130 | B23: =IFERROR($B$10*INDEX([2]Master!$B$3:$T$21,MATCH($A23,[2]Master!$A$3:$A$21,0),MATCH("S."&B$8,[2]Master!$B$2:$T$2,0)),0) -> 3.0985484 | C23: 121-130 | D23: =IFERROR($D$10*INDEX([2]Master!$B$3:$T$21,MATCH($A23,[2]Master!$A$3:$A$21,0),MATCH("S."&D$8,[2]Master!$B$2:$T$2,0)),0) -> 2.8403361 | E23: 121-130 | F23: =IFERROR($F$10*INDEX([2]Master!$B$3:$T$21,MATCH($A23,[2]Master!$A$3:$A$21,0),MATCH("S."&F$8,[2]Master!$B$2:$T$2,0)),0) -> 3.0985484 | G23: 121-130 | H23: =IFERROR($H$10*INDEX([2]Master!$B$3:$T$21,MATCH($A23,[2]Master!$A$3:$A$21,0),MATCH("S."&H$8,[2]Master!$B$2:$T$2,0)),0) -> 2.5821237 | I23: 121-130 | J23: =IFERROR($J$10*INDEX([2]Master!$B$3:$T$21,MATCH($A23,[2]Master!$A$3:$A$21,0),MATCH("S."&J$8,[2]Master!$B$2:$T$2,0)),0) -> 2.5821237 | K23: 121-130 | L23: =IFERROR($J$10*INDEX([2]Master!$B$3:$T$21,MATCH($A23,[2]Master!$A$3:$A$21,0),MATCH("S."&L$8,[2]Master!$B$2:$T$2,0)),0) -> 2.5821237 | M23: 121-130 | N23: =IFERROR($J$10*INDEX([2]Master!$B$3:$T$21,MATCH($A23,[2]Master!$A$3:$A$21,0),MATCH("S."&N$8,[2]Master!$B$2:$T$2,0)),0) -> 2.5821237 | O23: =SUM(B23:N23) -> 19.365928 | U23: Broken
A24: 131-140 | B24: =IFERROR($B$10*INDEX([2]Master!$B$3:$T$21,MATCH($A24,[2]Master!$A$3:$A$21,0),MATCH("S."&B$8,[2]Master!$B$2:$T$2,0)),0) -> 63.505115 | C24: 131-140 | D24: =IFERROR($D$10*INDEX([2]Master!$B$3:$T$21,MATCH($A24,[2]Master!$A$3:$A$21,0),MATCH("S."&D$8,[2]Master!$B$2:$T$2,0)),0) -> 58.213022 | E24: 131-140 | F24: =IFERROR($F$10*INDEX([2]Master!$B$3:$T$21,MATCH($A24,[2]Master!$A$3:$A$21,0),MATCH("S."&F$8,[2]Master!$B$2:$T$2,0)),0) -> 63.505115 | G24: 131-140 | H24: =IFERROR($H$10*INDEX([2]Master!$B$3:$T$21,MATCH($A24,[2]Master!$A$3:$A$21,0),MATCH("S."&H$8,[2]Master!$B$2:$T$2,0)),0) -> 52.920929 | I24: 131-140 | J24: =IFERROR($J$10*INDEX([2]Master!$B$3:$T$21,MATCH($A24,[2]Master!$A$3:$A$21,0),MATCH("S."&J$8,[2]Master!$B$2:$T$2,0)),0) -> 52.920929 | K24: 131-140 | L24: =IFERROR($J$10*INDEX([2]Master!$B$3:$T$21,MATCH($A24,[2]Master!$A$3:$A$21,0),MATCH("S."&L$8,[2]Master!$B$2:$T$2,0)),0) -> 52.920929 | M24: 131-140 | N24: =IFERROR($J$10*INDEX([2]Master!$B$3:$T$21,MATCH($A24,[2]Master!$A$3:$A$21,0),MATCH("S."&N$8,[2]Master!$B$2:$T$2,0)),0) -> 52.920929 | O24: =SUM(B24:N24) -> 396.90697 | U24: Broken
A25: ฝอยคัดทิ้ง >140 | B25: =B10-SUM(B11:B24) -> 66.899956 | C25: ฝอยคัดทิ้ง >140 | D25: =D10-SUM(D11:D24) -> 61.324959 | E25: ฝอยคัดทิ้ง >140 | F25: =F10-SUM(F11:F24) -> 66.899956 | G25: ฝอยคัดทิ้ง >140 | H25: =H10-SUM(H11:H24) -> 55.749963 | I25: ฝอยคัดทิ้ง >140 | J25: =J10-SUM(J11:J24) -> 55.749963 | K25: ฝอยคัดทิ้ง >140 | L25: =L10-SUM(L11:L24) -> 55.749963 | M25: ฝอยคัดทิ้ง >140 | N25: =N10-SUM(N11:N24) -> 55.749963 | O25: =SUM(B25:N25) -> 418.12472
A26: SUM | B26: =SUM(B11:B25) -> 6000 | C26: SUM | D26: =SUM(D11:D25) -> 5500 | E26: SUM | F26: =SUM(F11:F25) -> 6000 | G26: SUM | H26: =SUM(H11:H25) -> 5000 | I26: SUM | J26: =SUM(J11:J25) -> 5000 | K26: SUM | L26: =SUM(L11:L25) -> 5000 | M26: SUM | N26: =SUM(N11:N25) -> 5000 | O26: =SUM(B26:N26) -> 37500
A27: วิธีจับ | B27: แพ็ค | C27: วิธีจับ | D27: แพ็ค | E27: วิธีจับ | F27: แพ็ค | G27: วิธีจับ | H27: แพ็ค | I27: วิธีจับ | J27: แพ็ค | K27: วิธีจับ | L27: แพ็ค | M27: วิธีจับ | N27: แพ็ค
A28: Sal. (ppt) | B28: 20 | C28: Sal. (ppt) | D28: 20 | E28: Sal. (ppt) | F28: 20 | G28: Sal. (ppt) | H28: 20 | I28: Sal. (ppt) | J28: 20 | K28: Sal. (ppt) | L28: 20 | M28: Sal. (ppt) | N28: 20
A29: Remark | C29: Remark | E29: Remark | G29: Remark | I29: Remark | K29: Remark | M29: Remark
A30: %หักDefect | B30: 0.05 | C30: %หักDefect | D30: 0.05 | E30: %หักDefect | F30: 0.05 | G30: %หักDefect | H30: 0.05 | I30: %หักDefect | J30: 0.05 | K30: %หักDefect | L30: 0.05 | M30: %หักDefect | N30: 0.05
A31: Uniform | B31: 1.79 | C31: Uniform | D31: 1.79 | E31: Uniform | F31: 1.79 | G31: Uniform | H31: 1.79 | I31: Uniform | J31: 1.79 | K31: Uniform | L31: 1.79 | M31: Uniform | N31: 1.79
A32: แจ้งจับ ปิด/แบ่ง | B32: 10 | C32: แจ้งจับ ปิด/แบ่ง | D32: 10 | E32: แจ้งจับ ปิด/แบ่ง | F32: 10 | G32: แจ้งจับ ปิด/แบ่ง | H32: 10 | I32: แจ้งจับ ปิด/แบ่ง | J32: 10 | K32: แจ้งจับ ปิด/แบ่ง | L32: 10 | M32: แจ้งจับ ปิด/แบ่ง | N32: 10
A33: แบ่ง STD | B33: 5 | C33: แบ่ง STD | D33: 5 | E33: แบ่ง STD | F33: 5 | G33: แบ่ง STD | H33: 5 | I33: แบ่ง STD | J33: 5 | K33: แบ่ง STD | L33: 5 | M33: แบ่ง STD | N33: 5
A34: แบ่ง Premium | C34: แบ่ง Premium | E34: แบ่ง Premium | G34: แบ่ง Premium | I34: แบ่ง Premium | K34: แบ่ง Premium | M34: แบ่ง Premium
A35: แบ่ง ปัดใหญ่ | C35: แบ่ง ปัดใหญ่ | E35: แบ่ง ปัดใหญ่ | G35: แบ่ง ปัดใหญ่ | I35: แบ่ง ปัดใหญ่ | K35: แบ่ง ปัดใหญ่ | M35: แบ่ง ปัดใหญ่
A36: แบ่ง โรง2/ใต้ | C36: แบ่ง โรง2/ใต้ | E36: แบ่ง โรง2/ใต้ | G36: แบ่ง โรง2/ใต้ | I36: แบ่ง โรง2/ใต้ | K36: แบ่ง โรง2/ใต้ | M36: แบ่ง โรง2/ใต้
A37: แบ่งวันก่อน | C37: แบ่งวันก่อน | E37: แบ่งวันก่อน | G37: แบ่งวันก่อน | I37: แบ่งวันก่อน | K37: แบ่งวันก่อน | M37: แบ่งวันก่อน

Sheet Plan
B2: วันที่เริ่มต้นผลิต | C2: 46275
B3: วันที่สินสุด | C3: 46281
B5: แผนผลิต Date | C5: แผน LOAD Date | D5: No-. order | E5: Country | F5: Country2 | G5: Customer | H5: Group1 | I5: Group2 | J5: Product | K5: CODE | L5: Packing | M5: cups | N5: Pcs./Cup | O5: WT/Pcs | P5: RM | Q5: Dip | R5: Soup | S5: QTY | T5: Stock จริง | U5: Stock สำรอง | V5: Short/cs | W5: Short/cup | X5: Short Raw Wonton /Pcs. | Y5: ผงซุป/tray | Z5: ผงซุป | AA5: Remaek | AB5: WT/ PD | AC5: WT/ HO (Tons.) | AE5: WT | AF5: Order ถ้วย
B6: {=_xlfn.UNIQUE(_xlfn.HSTACK(_xlfn._xlws.FILTER(แผนผลิต!B5:C10000,(แผนผลิต!B5:B10000>=$C$2)*(แผนผลิต!B5:B10000<=$C$3)),_xlfn._xlws.FILTER(แผนผลิต!G5:AI10000,(แผนผลิต!B5:B10000>=$C$2)*(แผนผลิต!B5:B10000<=$C$3))))} -> 46275 | C6: 10-2026 | D6: ขายภายใน | E6: .7-11 | F6: CPFGS | G6: Seven ถ้วยดำ | H6: E+Wonton | I6: Cooked Wonton | J6: เกี๊ยวกุ้ง_ตราซีพี_(145กรัมx24)(7-11) | K6: 082S81A24005P04001 | L6: 145g*24 | M6: 24 | N6: 5 | O6: 0.008 | P6: M | Q6: STPP | R6: Regular | S6: 4842 | T6: 0 | U6: 0 | V6: -4842 | W6: 116208 | X6: 581040 | Y6: 0.0075 | Z6: 871.56 | AA6: 0 | AB6: 4.64832 | AC6: 8.608 | AD6: 0.145 | AE6: 16.85016 | AF6: 116208
B7: 46276 | C7: 10-2026 | D7: ขายภายใน | E7: .7-11 | F7: CPFGS | G7: ถ้วยใหม่ | H7: E+Wonton | I7: Cooked Wonton | J7: เกี๊ยวกุ้ง ตรา อีซี่ โก 24x5 PCS | K7: 082S81A24005P0E001 | L7: 135g*24 | M7: 24 | N7: 5 | O7: 0.0062 | P7: SS | Q7: STPP | R7: Regular | S7: 4842 | T7: 0 | U7: 0 | V7: -4842 | W7: 116208 | X7: 581040 | Y7: 0.0075 | Z7: 871.56 | AA7: 0 | AB7: 3.602448 | AC7: 6.6712 | AD7: 0.135 | AE7: 15.68808 | AF7: 116208
